Workbook

Sheet 안내(README)
A1: 두위드(Do With) 재무 모델링 연습용 36개월 데이터
A2: 주식회사 두위드 · 정보통신업 · 데이터베이스 및 온라인 정보 제공업 · B2C AI SaaS / 마켓플레이스 / 데이터 플랫폼 · 국내 개인·법인 고객
A3: 기간: 2025-05(설립) ~ 2028-04, 36개월 · 단위: 원 · 회계연도: 1~12월
A5: 데이터 구분(각 시트 4행 색상)
A6: 회색 = 실적배분: 2025-05~12월. 연간 합계는 2025 표준재무제표와 원 단위까지 일치, 월·세부항목 배분은 가정
A7: 하늘색 = 가상(실적 대체): 2026-01~09월. 실제 데이터를 받으면 이 구간부터 교체
A8: 주황색 = 가상(전망): 2026-10~2028-04월
A9: 글자색: 파란색 = 입력값(데이터), 검정 = 산식, 초록 = 다른 시트 연결 산식
A10: 시트 연결: 매출·매출원가·판관비 → 손익계산서 → 현금흐름표(간접법) → 재무상태표 현금. 재무상태표 36행 '검증'이 0이면 3개 재무제표가 맞물린 것입니다.
A12: 2025 표준재무제표 대사(실적 vs 이 파일)
A13: 항목 | B13: 2025 신고 실적 | C13: 이 파일 FY2025 | D13: 차이
A14: 매출액 | B14: 37277876 | C14: ='손익계산서(P&L)'!AP5 -> 37277876 | D14: =C14-B14 -> 0
A15: 매출원가+판관비 | B15: 83568716 | C15: ='손익계산서(P&L)'!AP9+'손익계산서(P&L)'!AP18 -> 83568716 | D15: =C15-B15 -> 0
A16: 영업손실 | B16: -46290840 | C16: ='손익계산서(P&L)'!AP24 -> -46290840 | D16: =C16-B16 -> 0
A17: 영업외수익 | B17: 23703137 | C17: ='손익계산서(P&L)'!AP27 -> 23703137 | D17: =C17-B17 -> 0
A18: 영업외비용 | B18: 438822 | C18: ='손익계산서(P&L)'!AP30 -> 438822 | D18: =C18-B18 -> 0
A19: 당기순손실 | B19: -23026525 | C19: ='손익계산서(P&L)'!AP35 -> -23026525 | D19: =C19-B19 -> 0
A20: 현금및현금성자산(12/31) | B20: 198790542 | C20: ='재무상태표(BS)'!AP7 -> 198790542 | D20: =C20-B20 -> 0
A21: 자산총계 | B21: 199742022 | C21: ='재무상태표(BS)'!AP16 -> 199742022 | D21: =C21-B21 -> 0
A22: 부채총계 | B22: 212768547 | C22: ='재무상태표(BS)'!AP29 -> 212768547 | D22: =C22-B22 -> 0
A23: 자본총계 | B23: -13026525 | C23: ='재무상태표(BS)'!AP34 -> -13026525 | D23: =C23-B23 -> 0

Sheet 매출(Revenue)
A1: 매출(Revenue) 월별 상세 (단위: 원, VAT 별도)
A2: ※ 분해축: 1)사업부문·플랜(a: Pro/Max/크레딧, b, c) → 2)결제주기·상품·셀러유형 → 3)고객유형(개인/법인). 2025-05~12월은 2025 표준손익계산서 매출액(37,277,876원)을 월·항목별로 배분한 값, 2026-01 이후는 연습용 가상 데이터. 연간구독은 결제액을 12개월 안분, 크레딧은 사용 시 인식, 입장권은 행사월 인식.
A3: 표준재무제표_계정과목 | B3: 그룹(Level1) | C3: 중분류(Level2) | D3: 소분류(Level3) | E3: 성격 | F3: 2025-05-31 | G3: 2025-06-30 | H3: 2025-07-31 | I3: 2025-08-31 | J3: 2025-09-30 | K3: 2025-10-31 | L3: 2025-11-30 | M3: 2025-12-31 | N3: 2026-01-31 | O3: 2026-02-28 | P3: 2026-03-31 | Q3: 2026-04-30 | R3: 2026-05-31 | S3: 2026-06-30 | T3: 2026-07-31 | U3: 2026-08-31 | V3: 2026-09-30 | W3: 2026-10-31 | X3: 2026-11-30 | Y3: 2026-12-31 | Z3: 2027-01-31 | AA3: 2027-02-28 | AB3: 2027-03-31 | AC3: 2027-04-30 | AD3: 2027-05-31 | AE3: 2027-06-30 | AF3: 2027-07-31 | AG3: 2027-08-31 | AH3: 2027-09-30 | AI3: 2027-10-31 | AJ3: 2027-11-30 | AK3: 2027-12-31 | AL3: 2028-01-31 | AM3: 2028-02-29 | AN3: 2028-03-31 | AO3: 2028-04-30 | AP3: FY2025(5~12월) | AQ3: FY2026 | AR3: FY2027 | AS3: FY2028(1~4월) | AT3: 참고_표준손익계산서 계정(세무신고 매핑)
A4: ※ 데이터구분 | F4: 실적배분 | G4: 실적배분 | H4: 실적배분 | I4: 실적배분 | J4: 실적배분 | K4: 실적배분 | L4: 실적배분 | M4: 실적배분 | N4: 가상 | O4: 가상 | P4: 가상 | Q4: 가상 | R4: 가상 | S4: 가상 | T4: 가상 | U4: 가상 | V4: 가상 | W4: 가상 | X4: 가상 | Y4: 가상 | Z4: 가상 | AA4: 가상 | AB4: 가상 | AC4: 가상 | AD4: 가상 | AE4: 가상 | AF4: 가상 | AG4: 가상 | AH4: 가상 | AI4: 가상 | AJ4: 가상 | AK4: 가상 | AL4: 가상 | AM4: 가상 | AN4: 가상 | AO4: 가상 | AP4: 연간 집계 | AQ4: 연간 집계 | AR4: 연간 집계 | AS4: 연간 집계
A5: 매출액 | B5: [a] AI 취업준비 SaaS - Pro 플랜 | C5: 월간 구독 | D5: 개인 | E5: 반복 | F5: 0 | G5: 0 | H5: 0 | I5: 0 | J5: 810000 | K5: 1404000 | L5: 1782000 | M5: 2016000 | N5: 2430000 | O5: 3006000 | P5: 3852000 | Q5: 4500000 | R5: 4842000 | S5: 5094000 | T5: 5526000 | U5: 6426000 | V5: 7812000 | W5: 8694000 | X5: 9108000 | Y5: 9216000 | Z5: 10026000 | AA5: 11250000 | AB5: 13086000 | AC5: 14328000 | AD5: 14778000 | AE5: 14994000 | AF5: 15498000 | AG5: 16812000 | AH5: 18864000 | AI5: 19962000 | AJ5: 20160000 | AK5: 19818000 | AL5: 20196000 | AM5: 21186000 | AN5: 23112000 | AO5: 24228000 | AP5: =SUM(F5:M5) -> 6012000 | AQ5: =SUM(N5:Y5) -> 70506000 | AR5: =SUM(Z5:AK5) -> 189576000 | AS5: =SUM(AL5:AO5) -> 88722000 | AT5: 매출액 (2025 신고: 국내상품매출)
A6: 매출액 | B6: [a] AI 취업준비 SaaS - Pro 플랜 | C6: 월간 구독 | D6: 법인 | E6: 반복 | F6: 0 | G6: 0 | H6: 0 | I6: 0 | J6: 0 | K6: 0 | L6: 0 | M6: 0 | N6: 0 | O6: 0 | P6: 0 | Q6: 0 | R6: 160000 | S6: 208000 | T6: 256000 | U6: 304000 | V6: 352000 | W6: 400000 | X6: 448000 | Y6: 496000 | Z6: 544000 | AA6: 592000 | AB6: 640000 | AC6: 688000 | AD6: 736000 | AE6: 784000 | AF6: 832000 | AG6: 880000 | AH6: 928000 | AI6: 960000 | AJ6: 960000 | AK6: 960000 | AL6: 960000 | AM6: 960000 | AN6: 960000 | AO6: 960000 | AP6: =SUM(F6:M6) -> 0 | AQ6: =SUM(N6:Y6) -> 2624000 | AR6: =SUM(Z6:AK6) -> 9504000 | AS6: =SUM(AL6:AO6) -> 3840000 | AT6: 매출액 (2025 신고: 국내상품매출)
A7: 매출액 | B7: [a] AI 취업준비 SaaS - Pro 플랜 | C7: 연간 구독 | D7: 개인 | E7: 반복(연간 선결제 → 12개월 안분 인식) | F7: 0 | G7: 0 | H7: 0 | I7: 0 | J7: 0 | K7: 0 | L7: 0 | M7: 0 | N7: 75000 | O7: 165000 | P7: 285000 | Q7: 405000 | R7: 495000 | S7: 600000 | T7: 705000 | U7: 885000 | V7: 1110000 | W7: 1305000 | X7: 1470000 | Y7: 1605000 | Z7: 1755000 | AA7: 1950000 | AB7: 2205000 | AC7: 2415000 | AD7: 2580000 | AE7: 2730000 | AF7: 2895000 | AG7: 3120000 | AH7: 3405000 | AI7: 3630000 | AJ7: 3795000 | AK7: 3930000 | AL7: 4080000 | AM7: 4275000 | AN7: 4515000 | AO7: 4710000 | AP7: =SUM(F7:M7) -> 0 | AQ7: =SUM(N7:Y7) -> 9105000 | AR7: =SUM(Z7:AK7) -> 34410000 | AS7: =SUM(AL7:AO7) -> 17580000 | AT7: 매출액 (2025 신고: 국내상품매출)
A8: 매출액 | B8: [a] AI 취업준비 SaaS - Pro 플랜 | C8: 연간 구독 | D8: 법인 | E8: 반복(연간 선결제 → 12개월 안분 인식) | F8: 0 | G8: 0 | H8: 0 | I8: 0 | J8: 0 | K8: 0 | L8: 0 | M8: 0 | N8: 0 | O8: 0 | P8: 1250000 | Q8: 1250000 | R8: 1250000 | S8: 1250000 | T8: 1250000 | U8: 1250000 | V8: 2250000 | W8: 2250000 | X8: 2250000 | Y8: 2250000 | Z8: 2250000 | AA8: 2250000 | AB8: 4500000 | AC8: 4500000 | AD8: 4500000 | AE8: 4500000 | AF8: 4500000 | AG8: 4500000 | AH8: 6175000 | AI8: 6175000 | AJ8: 6175000 | AK8: 6175000 | AL8: 6175000 | AM8: 6175000 | AN8: 5475000 | AO8: 5475000 | AP8: =SUM(F8:M8) -> 0 | AQ8: =SUM(N8:Y8) -> 16500000 | AR8: =SUM(Z8:AK8) -> 56200000 | AS8: =SUM(AL8:AO8) -> 23300000 | AT8: 매출액 (2025 신고: 국내상품매출)
A9: 매출액 | B9: [a] AI 취업준비 SaaS - Max 플랜 | C9: 월간 구독 | D9: 개인 | E9: 반복 | F9: 0 | G9: 0 | H9: 0 | I9: 0 | J9: 0 | K9: 432000 | L9: 720000 | M9: 936000 | N9: 1260000 | O9: 1656000 | P9: 2232000 | Q9: 2700000 | R9: 2988000 | S9: 3204000 | T9: 3564000 | U9: 4176000 | V9: 5076000 | W9: 5724000 | X9: 6048000 | Y9: 6228000 | Z9: 6768000 | AA9: 7524000 | AB9: 8676000 | AC9: 9504000 | AD9: 9864000 | AE9: 10080000 | AF9: 10440000 | AG9: 11304000 | AH9: 12600000 | AI9: 13356000 | AJ9: 13572000 | AK9: 13464000 | AL9: 13788000 | AM9: 14472000 | AN9: 15696000 | AO9: 16452000 | AP9: =SUM(F9:M9) -> 2088000 | AQ9: =SUM(N9:Y9) -> 44856000 | AR9: =SUM(Z9:AK9) -> 127152000 | AS9: =SUM(AL9:AO9) -> 60408000 | AT9: 매출액 (2025 신고: 국내상품매출)
A10: 매출액 | B10: [a] AI 취업준비 SaaS - Max 플랜 | C10: 월간 구독 | D10: 법인 | E10: 반복 | F10: 0 | G10: 0 | H10: 0 | I10: 0 | J10: 0 | K10: 0 | L10: 0 | M10: 0 | N10: 0 | O10: 0 | P10: 0 | Q10: 0 | R10: 0 | S10: 0 | T10: 0 | U10: 160000 | V10: 192000 | W10: 224000 | X10: 256000 | Y10: 288000 | Z10: 320000 | AA10: 352000 | AB10: 384000 | AC10: 416000 | AD10: 448000 | AE10: 480000 | AF10: 512000 | AG10: 544000 | AH10: 576000 | AI10: 608000 | AJ10: 640000 | AK10: 640000 | AL10: 640000 | AM10: 640000 | AN10: 640000 | AO10: 640000 | AP10: =SUM(F10:M10) -> 0 | AQ10: =SUM(N10:Y10) -> 1120000 | AR10: =SUM(Z10:AK10) -> 5920000 | AS10: =SUM(AL10:AO10) -> 2560000 | AT10: 매출액 (2025 신고: 국내상품매출)
A11: 매출액 | B11: [a] AI 취업준비 SaaS - Max 플랜 | C11: 연간 구독 | D11: 개인 | E11: 반복(연간 선결제 → 12개월 안분 인식) | F11: 0 | G11: 0 | H11: 0 | I11: 0 | J11: 0 | K11: 0 | L11: 0 | M11: 0 | N11: 60000 | O11: 150000 | P11: 300000 | Q11: 420000 | R11: 510000 | S11: 600000 | T11: 720000 | U11: 870000 | V11: 1110000 | W11: 1290000 | X11: 1470000 | Y11: 1590000 | Z11: 1770000 | AA11: 1950000 | AB11: 2190000 | AC11: 2430000 | AD11: 2580000 | AE11: 2730000 | AF11: 2910000 | AG11: 3120000 | AH11: 3390000 | AI11: 3630000 | AJ11: 3810000 | AK11: 3930000 | AL11: 4080000 | AM11: 4260000 | AN11: 4500000 | AO11: 4710000 | AP11: =SUM(F11:M11) -> 0 | AQ11: =SUM(N11:Y11) -> 9090000 | AR11: =SUM(Z11:AK11) -> 34440000 | AS11: =SUM(AL11:AO11) -> 17550000 | AT11: 매출액 (2025 신고: 국내상품매출)
A12: 매출액 | B12: [a] AI 취업준비 SaaS - Max 플랜 | C12: 연간 구독 | D12: 법인 | E12: 반복(연간 선결제 → 12개월 안분 인식) | F12: 0 | G12: 0 | H12: 0 | I12: 0 | J12: 0 | K12: 0 | L12: 0 | M12: 0 | N12: 0 | O12: 0 | P12: 0 | Q12: 0 | R12: 0 | S12: 0 | T12: 0 | U12: 0 | V12: 0 | W12: 0 | X12: 0 | Y12: 0 | Z12: 0 | AA12: 0 | AB12: 1000000 | AC12: 1000000 | AD12: 1000000 | AE12: 1000000 | AF12: 1000000 | AG12: 1000000 | AH12: 1000000 | AI12: 1000000 | AJ12: 1000000 | AK12: 1000000 | AL12: 1000000 | AM12: 1000000 | AN12: 800000 | AO12: 800000 | AP12: =SUM(F12:M12) -> 0 | AQ12: =SUM(N12:Y12) -> 0 | AR12: =SUM(Z12:AK12) -> 10000000 | AS12: =SUM(AL12:AO12) -> 3600000 | AT12: 매출액 (2025 신고: 국내상품매출)
A13: 매출액 | B13: [a] AI 취업준비 SaaS - 크레딧 | C13: 1회 구매(크레딧 충전) | D13: 개인 | E13: 일시(크레딧 사용 시 인식) | F13: 0 | G13: 0 | H13: 0 | I13: 0 | J13: 0 | K13: 0 | L13: 0 | M13: 0 | N13: 0 | O13: 752136 | P13: 1571592 | Q13: 1802592 | R13: 1576646 | S13: 1416586 | T13: 1617151 | U13: 2380186 | V13: 3635054 | W13: 3752722 | X13: 3088121 | Y13: 2442981 | Z13: 2896344 | AA13: 3978933 | AB13: 5766552 | AC13: 6109488 | AD13: 5050358 | AE13: 4336049 | AF13: 4684680 | AG13: 6415766 | AH13: 9042830 | AI13: 8830574 | AJ13: 6965753 | AK13: 5325219 | AL13: 5950296 | AM13: 7675347 | AN13: 10434072 | AO13: 10574784 | AP13: =SUM(F13:M13) -> 0 | AQ13: =SUM(N13:Y13) -> 24035767 | AR13: =SUM(Z13:AK13) -> 69402546 | AS13: =SUM(AL13:AO13) -> 34634499 | AT13: 매출액 (2025 신고: 국내상품매출)
A14: 매출액 | B14: [a] AI 취업준비 SaaS - 크레딧 | C14: 1회 구매(크레딧 충전) | D14: 법인 | E14: 일시(크레딧 사용 시 인식) | F14: 0 | G14: 0 | H14: 0 | I14: 0 | J14: 0 | K14: 0 | L14: 0 | M14: 0 | N14: 0 | O14: 0 | P14: 0 | Q14: 0 | R14: 0 | S14: 666667 | T14: 666667 | U14: 666667 | V14: 833333 | W14: 833333 | X14: 833333 | Y14: 1000000 | Z14: 1000000 | AA14: 1000000 | AB14: 1166667 | AC14: 1166667 | AD14: 1166667 | AE14: 1333333 | AF14: 1333333 | AG14: 1333333 | AH14: 1500000 | AI14: 1500000 | AJ14: 1500000 | AK14: 1666667 | AL14: 1666667 | AM14: 1666667 | AN14: 1833333 | AO14: 1833333 | AP14: =SUM(F14:M14) -> 0 | AQ14: =SUM(N14:Y14) -> 5500000 | AR14: =SUM(Z14:AK14) -> 15666667 | AS14: =SUM(AL14:AO14) -> 7000000 | AT14: 매출액 (2025 신고: 국내상품매출)
A15: 매출액 | B15: [b] 전자책 판매 중개수수료 | C15: 국내 | D15: 개인셀러 | E15: 판매발생시 발생 | F15: 0 | G15: 0 | H15: 0 | I15: 0 | J15: 0 | K15: 0 | L15: 0 | M15: 0 | N15: 0 | O15: 0 | P15: 504000 | Q15: 479002 | R15: 398297 | S15: 392481 | T15: 489427 | U15: 723265 | V15: 1001912 | W15: 888163 | X15: 738035 | Y15: 635922 | Z15: 849061 | AA15: 1077522 | AB15: 1423781 | AC15: 1266842 | AD15: 986171 | AE15: 909723 | AF15: 1061968 | AG15: 1469056 | AH15: 1904906 | AI15: 1580607 | AJ15: 1229361 | AK15: 991429 | AL15: 1296315 | AM15: 1610995 | AN15: 2084441 | AO15: 1816050 | AP15: =SUM(F15:M15) -> 0 | AQ15: =SUM(N15:Y15) -> 6250504 | AR15: =SUM(Z15:AK15) -> 14750427 | AS15: =SUM(AL15:AO15) -> 6807801 | AT15: 매출액 (2025 신고: 국내상품매출)
A16: 매출액 | B16: [b] 전자책 판매 중개수수료 | C16: 국내 | D16: 사업자셀러 | E16: 판매발생시 발생 | F16: 0 | G16: 0 | H16: 0 | I16: 0 | J16: 0 | K16: 0 | L16: 0 | M16: 0 | N16: 0 | O16: 0 | P16: 336000 | Q16: 327398 | R16: 279079 | S16: 281885 | T16: 360273 | U16: 545621 | V16: 774528 | W16: 703527 | X16: 598985 | Y16: 528771 | Z16: 723274 | AA16: 940309 | AB16: 1272774 | AC16: 1160058 | AD16: 925013 | AE16: 874048 | AF16: 1045112 | AG16: 1480856 | AH16: 1966854 | AI16: 1671671 | AJ16: 1331808 | AK16: 1100193 | AL16: 1473589 | AM16: 1876007 | AN16: 2486701 | AO16: 2219616 | AP16: =SUM(F16:M16) -> 0 | AQ16: =SUM(N16:Y16) -> 4736067 | AR16: =SUM(Z16:AK16) -> 14491970 | AS16: =SUM(AL16:AO16) -> 8055913 | AT16: 매출액 (2025 신고: 국내상품매출)
... A22: 매출액 | B22: [c] 컨퍼런스 입장권 | C22: 단체·기업 티켓 | D22: 법인 | E22: 일시(행사일 인식) | F22: 0 | G22: 0 | H22: 0 | I22: 0 | J22: 0 | K22: 0 | L22: 0 | M22: 0 | N22: 0 | O22: 0 | P22: 0 | Q22: 2000000 | R22: 0 | S22: 0 | T22: 0 | U22: 0 | V22: 0 | W22: 3000000 | X22: 0 | Y22: 0 | Z22: 0 | AA22: 0 | AB22: 0 | AC22: 4500000 | AD22: 0 | AE22: 0 | AF22: 0 | AG22: 0 | AH22: 0 | AI22: 6000000 | AJ22: 0 | AK22: 0 | AL22: 0 | AM22: 0 | AN22: 0 | AO22: 7000000 | AP22: =SUM(F22:M22) -> 0 | AQ22: =SUM(N22:Y22) -> 5000000 | AR22: =SUM(Z22:AK22) -> 10500000 | AS22: =SUM(AL22:AO22) -> 7000000 | AT22: 매출액 (2025 신고: 국내상품매출)
A24: 소계: [a] AI 취업준비 SaaS | F24: =SUM(F5:F14) -> 0 | G24: =SUM(G5:G14) -> 0 | H24: =SUM(H5:H14) -> 0 | I24: =SUM(I5:I14) -> 0 | J24: =SUM(J5:J14) -> 810000 | K24: =SUM(K5:K14) -> 1836000 | L24: =SUM(L5:L14) -> 2502000 | M24: =SUM(M5:M14) -> 2952000 | ... AS24: =SUM(AS5:AS14) -> 259194499
A25: 소계: [b] 전자책·강의 중개수수료 | F25: =SUM(F15:F18) -> 0 | G25: =SUM(G15:G18) -> 0 | H25: =SUM(H15:H18) -> 0 | I25: =SUM(I15:I18) -> 0 | J25: =SUM(J15:J18) -> 0 | K25: =SUM(K15:K18) -> 0 | L25: =SUM(L15:L18) -> 0 | M25: =SUM(M15:M18) -> 0 | ... AS25: =SUM(AS15:AS18) -> 28176459
A26: 소계: [c] 자체 콘텐츠·컨퍼런스 | F26: =SUM(F19:F22) -> 1500000 | G26: =SUM(G19:G22) -> 2600000 | H26: =SUM(H19:H22) -> 3200000 | I26: =SUM(I19:I22) -> 3600000 | J26: =SUM(J19:J22) -> 4200000 | K26: =SUM(K19:K22) -> 3900000 | L26: =SUM(L19:L22) -> 6700000 | M26: =SUM(M19:M22) -> 3477876 | ... AS26: =SUM(AS19:AS22) -> 53140931
A27: 합계: 매출(Revenue) | F27: =SUM(F5:F22) -> 1500000 | G27: =SUM(G5:G22) -> 2600000 | H27: =SUM(H5:H22) -> 3200000 | I27: =SUM(I5:I22) -> 3600000 | J27: =SUM(J5:J22) -> 5010000 | K27: =SUM(K5:K22) -> 5736000 | L27: =SUM(L5:L22) -> 9202000 | M27: =SUM(M5:M22) -> 6429876 | ... AS27: =SUM(AS5:AS22) -> 340511889

Sheet 매출원가(COGS)
A1: 매출원가(COGS) 월별 상세 (단위: 원)
A2: ※ 2025년은 신고서상 매출원가 0원·지급수수료 50,385,211원으로 처리된 금액 중 클라우드·LLM·PG·행사비를 매출원가로 재분류한 값. 마켓플레이스는 순액(수수료) 매출 인식을 가정해 '제3자 판매자 정산대금'은 0원, 정산대금은 재무상태표 '셀러 정산 예수금'으로 관리.
A3: 표준재무제표_계정과목 | B3: 그룹(Level1) | C3: 중분류(Level2) | D3: 소분류(Level3) | E3: 성격 | F3: 2025-05-31 | G3: 2025-06-30 | H3: 2025-07-31 | I3: 2025-08-31 | J3: 2025-09-30 | K3: 2025-10-31 | L3: 2025-11-30 | M3: 2025-12-31 | N3: 2026-01-31 | O3: 2026-02-28 | P3: 2026-03-31 | Q3: 2026-04-30 | R3: 2026-05-31 | S3: 2026-06-30 | T3: 2026-07-31 | U3: 2026-08-31 | V3: 2026-09-30 | W3: 2026-10-31 | X3: 2026-11-30 | Y3: 2026-12-31 | Z3: 2027-01-31 | AA3: 2027-02-28 | AB3: 2027-03-31 | AC3: 2027-04-30 | AD3: 2027-05-31 | AE3: 2027-06-30 | AF3: 2027-07-31 | AG3: 2027-08-31 | AH3: 2027-09-30 | AI3: 2027-10-31 | AJ3: 2027-11-30 | AK3: 2027-12-31 | AL3: 2028-01-31 | AM3: 2028-02-29 | AN3: 2028-03-31 | AO3: 2028-04-30 | AP3: FY2025(5~12월) | AQ3: FY2026 | AR3: FY2027 | AS3: FY2028(1~4월) | AT3: 참고_표준손익계산서 계정(세무신고 매핑)
A4: ※ 데이터구분 | F4: 실적배분 | G4: 실적배분 | H4: 실적배분 | I4: 실적배분 | J4: 실적배분 | K4: 실적배분 | L4: 실적배분 | M4: 실적배분 | N4: 가상 | O4: 가상 | P4: 가상 | Q4: 가상 | R4: 가상 | S4: 가상 | T4: 가상 | U4: 가상 | V4: 가상 | W4: 가상 | X4: 가상 | Y4: 가상 | Z4: 가상 | AA4: 가상 | AB4: 가상 | AC4: 가상 | AD4: 가상 | AE4: 가상 | AF4: 가상 | AG4: 가상 | AH4: 가상 | AI4: 가상 | AJ4: 가상 | AK4: 가상 | AL4: 가상 | AM4: 가상 | AN4: 가상 | AO4: 가상 | AP4: 연간 집계 | AQ4: 연간 집계 | AR4: 연간 집계 | AS4: 연간 집계
A5: 매출원가 | B5: 인프라비용 | C5: 클라우드 인프라(AWS·Vercel) | D5: [a] AI 취업준비 SaaS (리소스 태그·프로젝트 기준) | E5: 변동 | F5: 0 | G5: 0 | H5: 0 | I5: 0 | J5: 378350 | K5: 414260 | L5: 437570 | M5: 453320 | N5: 483875 | O5: 550520 | P5: 682171 | Q5: 737716 | R5: 763758 | S5: 806374 | T5: 850669 | U5: 949125 | V5: 1132964 | W5: 1206557 | X5: 1224001 | Y5: 1229059 | Z5: 1306527 | AA5: 1429643 | AB5: 1736498 | AC5: 1839500 | AD5: 1844606 | AE5: 1853858 | AF5: 1911175 | AG5: 2066018 | AH5: 2361829 | AI5: 2437805 | AJ5: 2400221 | AK5: 2341811 | AL5: 2398759 | AM5: 2530850 | AN5: 2728789 | AO5: 2813409 | AP5: =SUM(F5:M5) -> 1683500 | AQ5: =SUM(N5:Y5) -> 10616789 | AR5: =SUM(Z5:AK5) -> 23529491 | AS5: =SUM(AL5:AO5) -> 10471807 | AT5: 매출원가 > 지급수수료
A6: 매출원가 | B6: AI비용 | C6: LLM 토큰비용(OpenAI GPT·Anthropic Claude API) | D6: [a] AI 취업준비 SaaS 직접대응 | E6: 변동 | F6: 0 | G6: 0 | H6: 0 | I6: 0 | J6: 173250 | K6: 396900 | L6: 542150 | M6: 640500 | N6: 836850 | O6: 1359098 | P6: 2024338 | Q6: 2384341 | R6: 2496609 | S6: 2808264 | T6: 3093539 | U6: 3749526 | V6: 4564281 | W6: 4980457 | X6: 5003930 | Y6: 4978705 | Z6: 5452304 | AA6: 6244731 | AB6: 7324818 | AC6: 7885638 | AD6: 7802592 | AE6: 7794287 | AF6: 8123326 | AG6: 9090428 | AH6: 9995987 | AI6: 10338865 | AJ6: 9988936 | AK6: 9580272 | AL6: 9917514 | AM6: 10715549 | AN6: 11163949 | AO6: 11555899 | AP6: =SUM(F6:M6) -> 1752800 | AQ6: =SUM(N6:Y6) -> 38279938 | AR6: =SUM(Z6:AK6) -> 99622184 | AS6: =SUM(AL6:AO6) -> 43352911 | AT6: 매출원가 > 지급수수료
A7: 매출원가 | B7: 결제비용 | C7: PG 카드결제 수수료 | D7: [a] AI 취업준비 SaaS 직접대응 | E7: 변동 | F7: 0 | G7: 0 | H7: 0 | I7: 0 | J7: 26730 | K7: 60588 | L7: 82566 | M7: 97416 | N7: 176103 | O7: 261688 | P7: 360082 | Q7: 391157 | R7: 383811 | S7: 394044 | T7: 447658 | U7: 570264 | V7: 739409 | W7: 752764 | X7: 723089 | Y7: 693448 | Z7: 835981 | AA7: 987290 | AB7: 1226190 | AC7: 1249068 | AD7: 1173045 | AE7: 1157054 | AF7: 1240845 | AG7: 1471307 | AH7: 1768486 | AI7: 1712606 | AJ7: 1586327 | AK7: 1472994 | AL7: 1630609 | AM7: 1820783 | AN7: 2142779 | AO7: 2107460 | AP7: =SUM(F7:M7) -> 267300 | AQ7: =SUM(N7:Y7) -> 5893517 | AR7: =SUM(Z7:AK7) -> 15881193 | AS7: =SUM(AL7:AO7) -> 7701631 | AT7: 매출원가 > 지급수수료
A8: 매출원가 | B8: 인프라비용 | C8: 클라우드 인프라(AWS·Vercel) | D8: [b] 콘텐츠 중개 (리소스 태그·프로젝트 기준) | E8: 변동 | F8: 0 | G8: 0 | H8: 0 | I8: 0 | J8: 0 | K8: 0 | L8: 0 | M8: 0 | N8: 0 | O8: 0 | P8: 175200 | Q8: 174192 | R8: 181121 | S8: 181271 | T8: 189774 | U8: 209967 | V8: 234775 | W8: 226714 | X8: 215092 | Y8: 207285 | Z8: 227622 | AA8: 249987 | AB8: 284121 | AC8: 271165 | AD8: 245780 | AE8: 239737 | AF8: 256409 | AG8: 299549 | AH8: 347046 | AI8: 316165 | AJ8: 281370 | AK8: 257709 | AL8: 292638 | AM8: 329566 | AN8: 385394 | AO8: 357819 | AP8: =SUM(F8:M8) -> 0 | AQ8: =SUM(N8:Y8) -> 1995391 | AR8: =SUM(Z8:AK8) -> 3276660 | AS8: =SUM(AL8:AO8) -> 1365417 | AT8: 매출원가 > 지급수수료
A9: 매출원가 | B9: 결제비용 | C9: PG 카드결제 수수료 | D9: [b] 콘텐츠 중개 (거래액 기준) | E9: 변동 | F9: 0 | G9: 0 | H9: 0 | I9: 0 | J9: 0 | K9: 0 | L9: 0 | M9: 0 | N9: 0 | O9: 0 | P9: 126000 | Q9: 120960 | R9: 155606 | S9: 156355 | T9: 198870 | U9: 299836 | V9: 423877 | W9: 383571 | X9: 325458 | Y9: 286425 | Z9: 388110 | AA9: 499935 | AB9: 670606 | AC9: 605826 | AD9: 478902 | AE9: 448684 | AF9: 532045 | AG9: 747743 | AH9: 985228 | AI9: 830827 | AJ9: 656849 | AK9: 538547 | AL9: 713191 | AM9: 897828 | AN9: 1176971 | AO9: 1039097 | AP9: =SUM(F9:M9) -> 0 | AQ9: =SUM(N9:Y9) -> 2476958 | AR9: =SUM(Z9:AK9) -> 7383302 | AS9: =SUM(AL9:AO9) -> 3827087 | AT9: 매출원가 > 지급수수료
A10: 매출원가 | B10: 판매자정산 | C10: 제3자 판매자 정산대금(총액 매출 인식 시에만 사용) | D10: [b] 콘텐츠 중개 직접대응 | E10: 변동 | F10: 0 | G10: 0 | H10: 0 | I10: 0 | J10: 0 | K10: 0 | L10: 0 | M10: 0 | N10: 0 | O10: 0 | P10: 0 | Q10: 0 | R10: 0 | S10: 0 | T10: 0 | U10: 0 | V10: 0 | W10: 0 | X10: 0 | Y10: 0 | Z10: 0 | AA10: 0 | AB10: 0 | AC10: 0 | AD10: 0 | AE10: 0 | AF10: 0 | AG10: 0 | AH10: 0 | AI10: 0 | AJ10: 0 | AK10: 0 | AL10: 0 | AM10: 0 | AN10: 0 | AO10: 0 | AP10: =SUM(F10:M10) -> 0 | AQ10: =SUM(N10:Y10) -> 0 | AR10: =SUM(Z10:AK10) -> 0 | AS10: =SUM(AL10:AO10) -> 0 | AT10: 매출원가 > 상품매출원가 (순액 인식 시 손익 외 처리)
A11: 매출원가 | B11: 운영원가 | C11: 셀러 온보딩·창구 운영비 | D11: [b] 콘텐츠 중개 직접대응 | E11: 고정 | F11: 0 | G11: 0 | H11: 0 | I11: 0 | J11: 0 | K11: 0 | L11: 0 | M11: 0 | N11: 0 | O11: 600000 | P11: 900000 | Q11: 900000 | R11: 900000 | S11: 900000 | T11: 900000 | U11: 900000 | V11: 900000 | W11: 900000 | X11: 900000 | Y11: 900000 | Z11: 1300000 | AA11: 1300000 | AB11: 1300000 | AC11: 1300000 | AD11: 1300000 | AE11: 1300000 | AF11: 1300000 | AG11: 1300000 | AH11: 1300000 | AI11: 1300000 | AJ11: 1300000 | AK11: 1300000 | AL11: 1500000 | AM11: 1500000 | AN11: 1500000 | AO11: 1500000 | AP11: =SUM(F11:M11) -> 0 | AQ11: =SUM(N11:Y11) -> 9600000 | AR11: =SUM(Z11:AK11) -> 15600000 | AS11: =SUM(AL11:AO11) -> 6000000 | AT11: 매출원가 > 지급수수료
A12: 매출원가 | B12: 운영원가 | C12: CS 소프트웨어 구독료 | D12: [b] 콘텐츠 중개 직접대응 | E12: 고정 | F12: 0 | G12: 0 | H12: 0 | I12: 0 | J12: 0 | K12: 0 | L12: 0 | M12: 0 | N12: 0 | O12: 0 | P12: 110000 | Q12: 110000 | R12: 110000 | S12: 110000 | T12: 110000 | U12: 110000 | V12: 110000 | W12: 110000 | X12: 110000 | Y12: 110000 | Z12: 165000 | AA12: 165000 | AB12: 165000 | AC12: 165000 | AD12: 165000 | AE12: 165000 | AF12: 165000 | AG12: 165000 | AH12: 165000 | AI12: 165000 | AJ12: 165000 | AK12: 165000 | AL12: 165000 | AM12: 165000 | AN12: 165000 | AO12: 165000 | AP12: =SUM(F12:M12) -> 0 | AQ12: =SUM(N12:Y12) -> 1100000 | AR12: =SUM(Z12:AK12) -> 1980000 | AS12: =SUM(AL12:AO12) -> 660000 | AT12: 매출원가 > 지급수수료
A13: 매출원가 | B13: 운영원가 | C13: 기타 마켓플레이스 운영비 | D13: [b] 콘텐츠 중개 직접대응 | E13: 변동 | F13: 0 | G13: 0 | H13: 0 | I13: 0 | J13: 0 | K13: 0 | L13: 0 | M13: 0 | N13: 0 | O13: 0 | P13: 133600 | Q13: 132256 | R13: 141495 | S13: 141695 | T13: 153032 | U13: 179956 | V13: 213034 | W13: 202286 | X13: 186789 | Y13: 176380 | Z13: 203496 | AA13: 233316 | AB13: 278828 | AC13: 261554 | AD13: 227707 | AE13: 219649 | AF13: 241879 | AG13: 299398 | AH13: 362728 | AI13: 321554 | AJ13: 275160 | AK13: 243613 | AL13: 290184 | AM13: 339421 | AN13: 413859 | AO13: 377093 | AP13: =SUM(F13:M13) -> 0 | AQ13: =SUM(N13:Y13) -> 1660523 | AR13: =SUM(Z13:AK13) -> 3168882 | AS13: =SUM(AL13:AO13) -> 1420557 | AT13: 매출원가 > 지급수수료
A14: 매출원가 | B14: 행사원가 | C14: 장소 대관료 | D14: [c] 컨퍼런스 직접대응 | E14: 변동 | F14: 0 | G14: 0 | H14: 0 | I14: 0 | J14: 0 | K14: 0 | L14: 1800000 | M14: 0 | N14: 0 | O14: 0 | P14: 0 | Q14: 2500000 | R14: 0 | S14: 0 | T14: 0 | U14: 0 | V14: 0 | W14: 3000000 | X14: 0 | Y14: 0 | Z14: 0 | AA14: 0 | AB14: 0 | AC14: 3500000 | AD14: 0 | AE14: 0 | AF14: 0 | AG14: 0 | AH14: 0 | AI14: 4000000 | AJ14: 0 | AK14: 0 | AL14: 0 | AM14: 0 | AN14: 0 | AO14: 4500000 | AP14: =SUM(F14:M14) -> 1800000 | AQ14: =SUM(N14:Y14) -> 5500000 | AR14: =SUM(Z14:AK14) -> 7500000 | AS14: =SUM(AL14:AO14) -> 4500000 | AT14: 매출원가 > 임차료
A15: 매출원가 | B15: 행사원가 | C15: 행사 장치·시설비(무대·음향·영상) | D15: [c] 컨퍼런스 직접대응 | E15: 변동 | F15: 0 | G15: 0 | H15: 0 | I15: 0 | J15: 0 | K15: 0 | L15: 1200000 | M15: 0 | N15: 0 | O15: 0 | P15: 0 | Q15: 2000000 | R15: 0 | S15: 0 | T15: 0 | U15: 0 | V15: 0 | W15: 2500000 | X15: 0 | Y15: 0 | Z15: 0 | AA15: 0 | AB15: 0 | AC15: 3000000 | AD15: 0 | AE15: 0 | AF15: 0 | AG15: 0 | AH15: 0 | AI15: 3500000 | AJ15: 0 | AK15: 0 | AL15: 0 | AM15: 0 | AN15: 0 | AO15: 4000000 | AP15: =SUM(F15:M15) -> 1200000 | AQ15: =SUM(N15:Y15) -> 4500000 | AR15: =SUM(Z15:AK15) -> 6500000 | AS15: =SUM(AL15:AO15) -> 4000000 | AT15: 매출원가 > 외주용역비
A16: 매출원가 | B16: 결제비용 | C16: PG 카드결제 수수료 | D16: [c] 자체 콘텐츠·컨퍼런스 (콘텐츠·입장권 결제액 기준) | E16: 변동 | F16: 49500 | G16: 85800 | H16: 105600 | I16: 118800 | J16: 138600 | K16: 172260 | L16: 177540 | M16: 114770 | N16: 98010 | O16: 120988 | P16: 238024 | Q16: 258390 | R16: 101990 | S16: 91564 | T16: 104040 | U16: 140107 | V16: 301625 | W16: 330033 | X16: 108264 | Y16: 85047 | Z16: 110440 | AA16: 136332 | AB16: 353449 | AC16: 419015 | AD16: 114924 | AE16: 103177 | AF16: 117234 | AG16: 157876 | AH16: 417118 | AI16: 487749 | AJ16: 121995 | AK16: 95834 | AL16: 124447 | AM16: 153623 | AN16: 472035 | AO16: 582797 | AP16: =SUM(F16:M16) -> 962870 | AQ16: =SUM(N16:Y16) -> 1978082 | AR16: =SUM(Z16:AK16) -> 2635143 | AS16: =SUM(AL16:AO16) -> 1332902 | AT16: 매출원가 > 지급수수료
A18: 소계: [a] AI 취업준비 SaaS | F18: =SUM(F5:F7) -> 0 | G18: =SUM(G5:G7) -> 0 | H18: =SUM(H5:H7) -> 0 | I18: =SUM(I5:I7) -> 0 | J18: =SUM(J5:J7) -> 578330 | K18: =SUM(K5:K7) -> 871748 | L18: =SUM(L5:L7) -> 1062286 | M18: =SUM(M5:M7) -> 1191236 | ... AS18: =SUM(AS5:AS7) -> 61526349
A19: 소계: [b] 콘텐츠 중개 | F19: =SUM(F8:F13) -> 0 | G19: =SUM(G8:G13) -> 0 | H19: =SUM(H8:H13) -> 0 | I19: =SUM(I8:I13) -> 0 | J19: =SUM(J8:J13) -> 0 | K19: =SUM(K8:K13) -> 0 | L19: =SUM(L8:L13) -> 0 | M19: =SUM(M8:M13) -> 0 | ... AS19: =SUM(AS8:AS13) -> 13273061
A20: 소계: [c] 자체 콘텐츠·컨퍼런스 | F20: =SUM(F14:F16) -> 49500 | G20: =SUM(G14:G16) -> 85800 | H20: =SUM(H14:H16) -> 105600 | I20: =SUM(I14:I16) -> 118800 | J20: =SUM(J14:J16) -> 138600 | K20: =SUM(K14:K16) -> 172260 | L20: =SUM(L14:L16) -> 3177540 | M20: =SUM(M14:M16) -> 114770 | ... AS20: =SUM(AS14:AS16) -> 9832902
A21: 합계: 매출원가(COGS) | F21: =SUM(F5:F16) -> 49500 | G21: =SUM(G5:G16) -> 85800 | H21: =SUM(H5:H16) -> 105600 | I21: =SUM(I5:I16) -> 118800 | J21: =SUM(J5:J16) -> 716930 | K21: =SUM(K5:K16) -> 1044008 | L21: =SUM(L5:L16) -> 4239826 | M21: =SUM(M5:M16) -> 1306006 | ... AS21: =SUM(AS5:AS16) -> 84632312

Sheet 판관비(SG&A)
A1: 판관비(SG&A) 월별 상세 (단위: 원)
A2: ※ 2025년은 표준손익계산서 판관비 계정(급여·보험료·복리후생비·여비교통비·기업업무추진비·세금과공과·지급수수료·소모품비)을 5대 그룹으로 재분류. 지급수수료 중 매출원가·SaaS·자문·광고 외 잔액은 MVP 외주 개발비(R&D)로 가정.
A3: 표준재무제표_계정과목 | B3: 그룹(Level1) | C3: 중분류(Level2) | D3: 소분류(Level3) | E3: 성격 | F3: 2025-05-31 | G3: 2025-06-30 | H3: 2025-07-31 | I3: 2025-08-31 | J3: 2025-09-30 | K3: 2025-10-31 | L3: 2025-11-30 | M3: 2025-12-31 | N3: 2026-01-31 | O3: 2026-02-28 | P3: 2026-03-31 | Q3: 2026-04-30 | R3: 2026-05-31 | S3: 2026-06-30 | T3: 2026-07-31 | U3: 2026-08-31 | V3: 2026-09-30 | W3: 2026-10-31 | X3: 2026-11-30 | Y3: 2026-12-31 | Z3: 2027-01-31 | AA3: 2027-02-28 | AB3: 2027-03-31 | AC3: 2027-04-30 | AD3: 2027-05-31 | AE3: 2027-06-30 | AF3: 2027-07-31 | AG3: 2027-08-31 | AH3: 2027-09-30 | AI3: 2027-10-31 | AJ3: 2027-11-30 | AK3: 2027-12-31 | AL3: 2028-01-31 | AM3: 2028-02-29 | AN3: 2028-03-31 | AO3: 2028-04-30 | AP3: FY2025(5~12월) | AQ3: FY2026 | AR3: FY2027 | AS3: FY2028(1~4월) | AT3: 참고_표준손익계산서 계정(세무신고 매핑)
A4: ※ 데이터구분 | F4: 실적배분 | G4: 실적배분 | H4: 실적배분 | I4: 실적배분 | J4: 실적배분 | K4: 실적배분 | L4: 실적배분 | M4: 실적배분 | N4: 가상 | O4: 가상 | P4: 가상 | Q4: 가상 | R4: 가상 | S4: 가상 | T4: 가상 | U4: 가상 | V4: 가상 | W4: 가상 | X4: 가상 | Y4: 가상 | Z4: 가상 | AA4: 가상 | AB4: 가상 | AC4: 가상 | AD4: 가상 | AE4: 가상 | AF4: 가상 | AG4: 가상 | AH4: 가상 | AI4: 가상 | AJ4: 가상 | AK4: 가상 | AL4: 가상 | AM4: 가상 | AN4: 가상 | AO4: 가상 | AP4: 연간 집계 | AQ4: 연간 집계 | AR4: 연간 집계 | AS4: 연간 집계
A5: 판매비와관리비 | B5: Labor Costs(인건비) | C5: 부서별 급여(인원은 KPI 시트 참조) | D5: 개발조직 급여 | E5: 고정 | F5: 0 | G5: 2999024 | H5: 2999024 | I5: 2999024 | J5: 2999024 | K5: 2999024 | L5: 2999024 | M5: 2999021 | N5: 7800000 | O5: 7800000 | P5: 7800000 | Q5: 12600000 | R5: 12600000 | S5: 12600000 | T5: 12600000 | U5: 12600000 | V5: 12600000 | W5: 12600000 | X5: 12600000 | Y5: 12600000 | Z5: 13230000 | AA5: 13230000 | AB5: 13230000 | AC5: 13230000 | AD5: 13230000 | AE5: 13230000 | AF5: 13230000 | AG5: 13230000 | AH5: 18480000 | AI5: 18480000 | AJ5: 18480000 | AK5: 18480000 | AL5: 19404000 | AM5: 19404000 | AN5: 19404000 | AO5: 19404000 | AP5: =SUM(F5:M5) -> 20993165 | AQ5: =SUM(N5:Y5) -> 136800000 | AR5: =SUM(Z5:AK5) -> 179760000 | AS5: =SUM(AL5:AO5) -> 77616000 | AT5: 급여 > 직원급여
A6: 판매비와관리비 | B6: Labor Costs(인건비) | C6: 부서별 급여(인원은 KPI 시트 참조) | D6: 사업·마케팅조직 급여 | E6: 고정 | F6: 0 | G6: 0 | H6: 0 | I6: 0 | J6: 0 | K6: 0 | L6: 0 | M6: 0 | N6: 0 | O6: 0 | P6: 0 | Q6: 3400000 | R6: 3400000 | S6: 3400000 | T6: 3400000 | U6: 3400000 | V6: 3400000 | W6: 3400000 | X6: 3400000 | Y6: 3400000 | Z6: 3570000 | AA6: 3570000 | AB6: 7350000 | AC6: 7350000 | AD6: 7350000 | AE6: 7350000 | AF6: 7350000 | AG6: 7350000 | AH6: 7350000 | AI6: 7350000 | AJ6: 7350000 | AK6: 7350000 | AL6: 7717500 | AM6: 7717500 | AN6: 7717500 | AO6: 7717500 | AP6: =SUM(F6:M6) -> 0 | AQ6: =SUM(N6:Y6) -> 30600000 | AR6: =SUM(Z6:AK6) -> 80640000 | AS6: =SUM(AL6:AO6) -> 30870000 | AT6: 급여 > 직원급여
A7: 판매비와관리비 | B7: Labor Costs(인건비) | C7: 부서별 급여(인원은 KPI 시트 참조) | D7: 경영지원·운영조직 급여 | E7: 고정 | F7: 0 | G7: 0 | H7: 0 | I7: 0 | J7: 1669457 | K7: 1669457 | L7: 1669457 | M7: 1669457 | N7: 3000000 | O7: 3000000 | P7: 3000000 | Q7: 3000000 | R7: 3000000 | S7: 3000000 | T7: 7000000 | U7: 7000000 | V7: 7000000 | W7: 7000000 | X7: 7000000 | Y7: 7000000 | Z7: 7350000 | AA7: 7350000 | AB7: 7350000 | AC7: 7350000 | AD7: 7350000 | AE7: 10710000 | AF7: 10710000 | AG7: 10710000 | AH7: 10710000 | AI7: 10710000 | AJ7: 10710000 | AK7: 10710000 | AL7: 11245500 | AM7: 11245500 | AN7: 11245500 | AO7: 11245500 | AP7: =SUM(F7:M7) -> 6677828 | AQ7: =SUM(N7:Y7) -> 60000000 | AR7: =SUM(Z7:AK7) -> 111720000 | AS7: =SUM(AL7:AO7) -> 44982000 | AT7: 급여 > 직원급여
A8: 판매비와관리비 | B8: Labor Costs(인건비) | C8: 퇴직급여 | D8: 퇴직급여(퇴직연금 부담금) | E8: 고정 | F8: 0 | G8: 0 | H8: 0 | I8: 0 | J8: 0 | K8: 0 | L8: 0 | M8: 0 | N8: 900000 | O8: 900000 | P8: 900000 | Q8: 1583333 | R8: 1583333 | S8: 1583333 | T8: 1916667 | U8: 1916667 | V8: 1916667 | W8: 1916667 | X8: 1916667 | Y8: 1916667 | Z8: 2012500 | AA8: 2012500 | AB8: 2327500 | AC8: 2327500 | AD8: 2327500 | AE8: 2607500 | AF8: 2607500 | AG8: 2607500 | AH8: 3045000 | AI8: 3045000 | AJ8: 3045000 | AK8: 3045000 | AL8: 3197250 | AM8: 3197250 | AN8: 3197250 | AO8: 3197250 | AP8: =SUM(F8:M8) -> 0 | AQ8: =SUM(N8:Y8) -> 18950001 | AR8: =SUM(Z8:AK8) -> 31010000 | AS8: =SUM(AL8:AO8) -> 12789000 | AT8: 퇴직급여
A9: 판매비와관리비 | B9: Labor Costs(인건비) | C9: 법정부담금 | D9: 4대보험료(회사부담분) | E9: 고정 | F9: 0 | G9: 50221 | H9: 50221 | I9: 50221 | J9: 78177 | K9: 78177 | L9: 78177 | M9: 78176 | N9: 1058400 | O9: 1058400 | P9: 1058400 | Q9: 1862000 | R9: 1862000 | S9: 1862000 | T9: 2254000 | U9: 2254000 | V9: 2254000 | W9: 2254000 | X9: 2254000 | Y9: 2254000 | Z9: 2366700 | AA9: 2366700 | AB9: 2737140 | AC9: 2737140 | AD9: 2737140 | AE9: 3066420 | AF9: 3066420 | AG9: 3066420 | AH9: 3580920 | AI9: 3580920 | AJ9: 3580920 | AK9: 3580920 | AL9: 3759966 | AM9: 3759966 | AN9: 3759966 | AO9: 3759966 | AP9: =SUM(F9:M9) -> 463370 | AQ9: =SUM(N9:Y9) -> 22285200 | AR9: =SUM(Z9:AK9) -> 36467760 | AS9: =SUM(AL9:AO9) -> 15039864 | AT9: 보험료 / 복리후생비
A10: 판매비와관리비 | B10: Labor Costs(인건비) | C10: 복리후생 | D10: 복리후생비(식대·경조사·건강검진 등) | E10: 변동 | F10: 0 | G10: 261448 | H10: 261448 | I10: 261448 | J10: 406987 | K10: 406987 | L10: 406987 | M10: 406984 | N10: 750000 | O10: 1350000 | P10: 750000 | Q10: 1250000 | R10: 1250000 | S10: 1250000 | T10: 1500000 | U10: 1500000 | V10: 2700000 | W10: 1500000 | X10: 1500000 | Y10: 1500000 | Z10: 1500000 | AA10: 2700000 | AB10: 1750000 | AC10: 1750000 | AD10: 1750000 | AE10: 2000000 | AF10: 2000000 | AG10: 2000000 | AH10: 4050000 | AI10: 2250000 | AJ10: 2250000 | AK10: 2250000 | AL10: 2250000 | AM10: 4050000 | AN10: 2250000 | AO10: 2250000 | AP10: =SUM(F10:M10) -> 2412289 | AQ10: =SUM(N10:Y10) -> 16800000 | AR10: =SUM(Z10:AK10) -> 26250000 | AS10: =SUM(AL10:AO10) -> 10800000 | AT10: 복리후생비
A11: 판매비와관리비 | B11: D&A(감가상각·무형자산상각) | C11: 유형자산상각 | D11: 유형자산 감가상각비(노트북·서버·비품) | E11: 고정 | F11: 0 | G11: 0 | H11: 0 | I11: 0 | J11: 0 | K11: 0 | L11: 0 | M11: 0 | N11: 0 | O11: 83333 | P11: 83333 | Q11: 83333 | R11: 156667 | S11: 156667 | T11: 156667 | U11: 193333 | V11: 193333 | W11: 193333 | X11: 193333 | Y11: 193333 | Z11: 343333 | AA11: 343333 | AB11: 343333 | AC11: 380000 | AD11: 380000 | AE11: 380000 | AF11: 380000 | AG11: 380000 | AH11: 380000 | AI11: 420000 | AJ11: 420000 | AK11: 420000 | AL11: 420000 | AM11: 420000 | AN11: 420000 | AO11: 420000 | AP11: =SUM(F11:M11) -> 0 | AQ11: =SUM(N11:Y11) -> 1686665 | AR11: =SUM(Z11:AK11) -> 4569999 | AS11: =SUM(AL11:AO11) -> 1680000 | AT11: 감가상각비
A12: 판매비와관리비 | B12: D&A(감가상각·무형자산상각) | C12: 무형자산상각 | D12: 무형자산 상각비(개발비 자산화분·SW 라이선스) | E12: 고정 | F12: 0 | G12: 0 | H12: 0 | I12: 0 | J12: 0 | K12: 0 | L12: 0 | M12: 0 | N12: 0 | O12: 0 | P12: 25000 | Q12: 25000 | R12: 25000 | S12: 25000 | T12: 25000 | U12: 25000 | V12: 25000 | W12: 25000 | X12: 25000 | Y12: 25000 | Z12: 25000 | AA12: 25000 | AB12: 25000 | AC12: 25000 | AD12: 25000 | AE12: 58333 | AF12: 58333 | AG12: 58333 | AH12: 58333 | AI12: 58333 | AJ12: 58333 | AK12: 58333 | AL12: 58333 | AM12: 58333 | AN12: 58333 | AO12: 58333 | AP12: =SUM(F12:M12) -> 0 | AQ12: =SUM(N12:Y12) -> 250000 | AR12: =SUM(Z12:AK12) -> 533331 | AS12: =SUM(AL12:AO12) -> 233332 | AT12: 무형자산상각비
A13: 판매비와관리비 | B13: R&D(연구개발비) | C13: 외주비 | D13: 외주 개발비 | E13: 변동 | F13: 6883054 | G13: 6883054 | H13: 6883054 | I13: 4588702 | J13: 2294351 | K13: 1147176 | L13: 1147176 | M13: 1147174 | N13: 3000000 | O13: 3000000 | P13: 3000000 | Q13: 2000000 | R13: 2000000 | S13: 2000000 | T13: 2000000 | U13: 2000000 | V13: 2000000 | W13: 2000000 | X13: 4000000 | Y13: 4000000 | Z13: 4000000 | AA13: 4000000 | AB13: 4000000 | AC13: 4000000 | AD13: 4000000 | AE13: 4000000 | AF13: 4000000 | AG13: 4000000 | AH13: 4000000 | AI13: 4000000 | AJ13: 4000000 | AK13: 4000000 | AL13: 4000000 | AM13: 4000000 | AN13: 4000000 | AO13: 4000000 | AP13: =SUM(F13:M13) -> 30973741 | AQ13: =SUM(N13:Y13) -> 31000000 | AR13: =SUM(Z13:AK13) -> 48000000 | AS13: =SUM(AL13:AO13) -> 16000000 | AT13: 경상연구개발비
A14: 판매비와관리비 | B14: R&D(연구개발비) | C14: 개발환경 | D14: 개발·테스트용 클라우드·LLM 사용료 | E14: 변동 | F14: 0 | G14: 300000 | H14: 300000 | I14: 300000 | J14: 200000 | K14: 200000 | L14: 200000 | M14: 200000 | N14: 350000 | O14: 350000 | P14: 350000 | Q14: 350000 | R14: 350000 | S14: 350000 | T14: 350000 | U14: 350000 | V14: 350000 | W14: 350000 | X14: 350000 | Y14: 350000 | Z14: 500000 | AA14: 500000 | AB14: 500000 | AC14: 500000 | AD14: 500000 | AE14: 500000 | AF14: 500000 | AG14: 500000 | AH14: 500000 | AI14: 500000 | AJ14: 500000 | AK14: 500000 | AL14: 500000 | AM14: 500000 | AN14: 500000 | AO14: 500000 | AP14: =SUM(F14:M14) -> 1700000 | AQ14: =SUM(N14:Y14) -> 4200000 | AR14: =SUM(Z14:AK14) -> 6000000 | AS14: =SUM(AL14:AO14) -> 2000000 | AT14: 경상연구개발비
A15: 판매비와관리비 | B15: R&D(연구개발비) | C15: 기타 | D15: 기타 연구개발비(데이터·도구 구입 등) | E15: 변동 | F15: 0 | G15: 0 | H15: 0 | I15: 0 | J15: 0 | K15: 0 | L15: 0 | M15: 0 | N15: 0 | O15: 0 | P15: 500000 | Q15: 500000 | R15: 500000 | S15: 500000 | T15: 500000 | U15: 500000 | V15: 500000 | W15: 500000 | X15: 500000 | Y15: 500000 | Z15: 800000 | AA15: 800000 | AB15: 800000 | AC15: 800000 | AD15: 800000 | AE15: 800000 | AF15: 800000 | AG15: 800000 | AH15: 800000 | AI15: 800000 | AJ15: 800000 | AK15: 800000 | AL15: 800000 | AM15: 800000 | AN15: 800000 | AO15: 800000 | AP15: =SUM(F15:M15) -> 0 | AQ15: =SUM(N15:Y15) -> 5000000 | AR15: =SUM(Z15:AK15) -> 9600000 | AS15: =SUM(AL15:AO15) -> 3200000 | AT15: 경상연구개발비
A16: 판매비와관리비 | B16: S&M(판매및마케팅비) | C16: 퍼포먼스마케팅 | D16: 광고선전비 - [a] AI 취업준비 SaaS 구독자 획득 | E16: 변동 | F16: 0 | G16: 0 | H16: 0 | I16: 0 | J16: 800000 | K16: 900000 | L16: 700000 | M16: 600000 | N16: 1120000 | O16: 1500000 | P16: 2080000 | Q16: 1940000 | R16: 1600000 | S16: 1540000 | T16: 1900000 | U16: 2740000 | V16: 3740000 | W16: 3260000 | X16: 2680000 | Y16: 2260000 | Z16: 3816000 | AA16: 4800000 | AB16: 6288000 | AC16: 5544000 | AD16: 4296000 | AE16: 3912000 | AF16: 4536000 | AG16: 6240000 | AH16: 8040000 | AI16: 6624000 | AJ16: 5112000 | AK16: 4104000 | AL16: 5876000 | AM16: 7332000 | AN16: 9516000 | AO16: 8320000 | AP16: =SUM(F16:M16) -> 3000000 | AQ16: =SUM(N16:Y16) -> 26360000 | AR16: =SUM(Z16:AK16) -> 63312000 | AS16: =SUM(AL16:AO16) -> 31044000 | AT16: 광고선전비
... A31: 판매비와관리비 | B31: Other G&A(기타관리비) | C31: 기타 | D31: 기타판관비 | E31: 변동 | F31: 0 | G31: 0 | H31: 0 | I31: 0 | J31: 0 | K31: 0 | L31: 0 | M31: 0 | N31: 80000 | O31: 80000 | P31: 80000 | Q31: 80000 | R31: 80000 | S31: 80000 | T31: 80000 | U31: 80000 | V31: 80000 | W31: 80000 | X31: 80000 | Y31: 80000 | Z31: 150000 | AA31: 150000 | AB31: 150000 | AC31: 150000 | AD31: 150000 | AE31: 150000 | AF31: 150000 | AG31: 150000 | AH31: 150000 | AI31: 150000 | AJ31: 150000 | AK31: 150000 | AL31: 150000 | AM31: 150000 | AN31: 150000 | AO31: 150000 | AP31: =SUM(F31:M31) -> 0 | AQ31: =SUM(N31:Y31) -> 960000 | AR31: =SUM(Z31:AK31) -> 1800000 | AS31: =SUM(AL31:AO31) -> 600000 | AT31: 잡비 등
A33: 소계: Labor Costs(인건비) | F33: =SUM(F5:F10) -> 0 | G33: =SUM(G5:G10) -> 3310693 | H33: =SUM(H5:H10) -> 3310693 | I33: =SUM(I5:I10) -> 3310693 | J33: =SUM(J5:J10) -> 5153645 | K33: =SUM(K5:K10) -> 5153645 | L33: =SUM(L5:L10) -> 5153645 | M33: =SUM(M5:M10) -> 5153638 | ... AS33: =SUM(AS5:AS10) -> 192096864
A34: 소계: D&A(감가상각·무형자산상각) | F34: =SUM(F11:F12) -> 0 | G34: =SUM(G11:G12) -> 0 | H34: =SUM(H11:H12) -> 0 | I34: =SUM(I11:I12) -> 0 | J34: =SUM(J11:J12) -> 0 | K34: =SUM(K11:K12) -> 0 | L34: =SUM(L11:L12) -> 0 | M34: =SUM(M11:M12) -> 0 | ... AS34: =SUM(AS11:AS12) -> 1913332
A35: 소계: R&D(연구개발비) | F35: =SUM(F13:F15) -> 6883054 | G35: =SUM(G13:G15) -> 7183054 | H35: =SUM(H13:H15) -> 7183054 | I35: =SUM(I13:I15) -> 4888702 | J35: =SUM(J13:J15) -> 2494351 | K35: =SUM(K13:K15) -> 1347176 | L35: =SUM(L13:L15) -> 1347176 | M35: =SUM(M13:M15) -> 1347174 | ... AS35: =SUM(AS13:AS15) -> 21200000
A36: 소계: S&M(판매및마케팅비) | F36: =SUM(F16:F19) -> 0 | G36: =SUM(G16:G19) -> 300000 | H36: =SUM(H16:H19) -> 300000 | I36: =SUM(I16:I19) -> 600000 | J36: =SUM(J16:J19) -> 1400000 | K36: =SUM(K16:K19) -> 2100000 | L36: =SUM(L16:L19) -> 1200000 | M36: =SUM(M16:M19) -> 1100000 | ... AS36: =SUM(AS16:AS19) -> 46471087
A37: 소계: Other G&A(기타관리비) | F37: =SUM(F20:F31) -> 1660495 | G37: =SUM(G20:G31) -> 476613 | H37: =SUM(H20:H31) -> 476613 | I37: =SUM(I20:I31) -> 476257 | J37: =SUM(J20:J31) -> 568553 | K37: =SUM(K20:K31) -> 669257 | L37: =SUM(L20:L31) -> 697492 | M37: =SUM(M20:M31) -> 656573 | ... AS37: =SUM(AS20:AS31) -> 23032000
A38: 합계: 판관비(SG&A) | F38: =SUM(F5:F31) -> 8543549 | G38: =SUM(G5:G31) -> 11270360 | H38: =SUM(H5:H31) -> 11270360 | I38: =SUM(I5:I31) -> 9275652 | J38: =SUM(J5:J31) -> 9616549 | K38: =SUM(K5:K31) -> 9270078 | L38: =SUM(L5:L31) -> 8398313 | M38: =SUM(M5:M31) -> 8257385 | ... AS38: =SUM(AS5:AS31) -> 284713283

Sheet 손익계산서(P&L)
A1: 손익계산서(P&L) 월별 요약 (단위: 원)
A2: ※ 매출·매출원가·판관비는 상세 시트 합계를 연결(초록색). 영업외손익은 입력값(파란색): 2025년은 표준손익계산서 실적, 2026년 이후 정부보조금은 초기창업패키지(2026-05~11, 월 700만원)·TIPS R&D(2026-11~, 월 1,600만원) 가정.
A3: 항목 | B3: 산식·비고 | F3: 2025-05-31 | G3: 2025-06-30 | H3: 2025-07-31 | I3: 2025-08-31 | J3: 2025-09-30 | K3: 2025-10-31 | L3: 2025-11-30 | M3: 2025-12-31 | N3: 2026-01-31 | O3: 2026-02-28 | P3: 2026-03-31 | Q3: 2026-04-30 | R3: 2026-05-31 | S3: 2026-06-30 | T3: 2026-07-31 | U3: 2026-08-31 | V3: 2026-09-30 | W3: 2026-10-31 | X3: 2026-11-30 | Y3: 2026-12-31 | Z3: 2027-01-31 | AA3: 2027-02-28 | AB3: 2027-03-31 | AC3: 2027-04-30 | AD3: 2027-05-31 | AE3: 2027-06-30 | AF3: 2027-07-31 | AG3: 2027-08-31 | AH3: 2027-09-30 | AI3: 2027-10-31 | AJ3: 2027-11-30 | AK3: 2027-12-31 | AL3: 2028-01-31 | AM3: 2028-02-29 | AN3: 2028-03-31 | AO3: 2028-04-30 | AP3: FY2025(5~12월) | AQ3: FY2026 | AR3: FY2027 | AS3: FY2028(1~4월) | AT3: 참고_표준손익계산서 계정
A4: ※ 데이터구분 | F4: 실적배분 | G4: 실적배분 | H4: 실적배분 | I4: 실적배분 | J4: 실적배분 | K4: 실적배분 | L4: 실적배분 | M4: 실적배분 | N4: 가상 | O4: 가상 | P4: 가상 | Q4: 가상 | R4: 가상 | S4: 가상 | T4: 가상 | U4: 가상 | V4: 가상 | W4: 가상 | X4: 가상 | Y4: 가상 | Z4: 가상 | AA4: 가상 | AB4: 가상 | AC4: 가상 | AD4: 가상 | AE4: 가상 | AF4: 가상 | AG4: 가상 | AH4: 가상 | AI4: 가상 | AJ4: 가상 | AK4: 가상 | AL4: 가상 | AM4: 가상 | AN4: 가상 | AO4: 가상 | AP4: 연간 집계 | AQ4: 연간 집계 | AR4: 연간 집계 | AS4: 연간 집계
A5: 매출액 | F5: ='매출(Revenue)'!F27 -> 1500000 | G5: ='매출(Revenue)'!G27 -> 2600000 | H5: ='매출(Revenue)'!H27 -> 3200000 | I5: ='매출(Revenue)'!I27 -> 3600000 | J5: ='매출(Revenue)'!J27 -> 5010000 | K5: ='매출(Revenue)'!K27 -> 5736000 | L5: ='매출(Revenue)'!L27 -> 9202000 | M5: ='매출(Revenue)'!M27 -> 6429876 | ... AS5: ='매출(Revenue)'!AS27 -> 340511889 | AT5: Ⅰ.매출액
A6: [a] AI 취업준비 SaaS | F6: ='매출(Revenue)'!F24 -> 0 | G6: ='매출(Revenue)'!G24 -> 0 | H6: ='매출(Revenue)'!H24 -> 0 | I6: ='매출(Revenue)'!I24 -> 0 | J6: ='매출(Revenue)'!J24 -> 810000 | K6: ='매출(Revenue)'!K24 -> 1836000 | L6: ='매출(Revenue)'!L24 -> 2502000 | M6: ='매출(Revenue)'!M24 -> 2952000 | ... AS6: ='매출(Revenue)'!AS24 -> 259194499
A7: [b] 전자책·강의 중개수수료 | F7: ='매출(Revenue)'!F25 -> 0 | G7: ='매출(Revenue)'!G25 -> 0 | H7: ='매출(Revenue)'!H25 -> 0 | I7: ='매출(Revenue)'!I25 -> 0 | J7: ='매출(Revenue)'!J25 -> 0 | K7: ='매출(Revenue)'!K25 -> 0 | L7: ='매출(Revenue)'!L25 -> 0 | M7: ='매출(Revenue)'!M25 -> 0 | ... AS7: ='매출(Revenue)'!AS25 -> 28176459
A8: [c] 자체 콘텐츠·컨퍼런스 | F8: ='매출(Revenue)'!F26 -> 1500000 | G8: ='매출(Revenue)'!G26 -> 2600000 | H8: ='매출(Revenue)'!H26 -> 3200000 | I8: ='매출(Revenue)'!I26 -> 3600000 | J8: ='매출(Revenue)'!J26 -> 4200000 | K8: ='매출(Revenue)'!K26 -> 3900000 | L8: ='매출(Revenue)'!L26 -> 6700000 | M8: ='매출(Revenue)'!M26 -> 3477876 | ... AS8: ='매출(Revenue)'!AS26 -> 53140931
A9: 매출원가 | F9: ='매출원가(COGS)'!F21 -> 49500 | G9: ='매출원가(COGS)'!G21 -> 85800 | H9: ='매출원가(COGS)'!H21 -> 105600 | I9: ='매출원가(COGS)'!I21 -> 118800 | J9: ='매출원가(COGS)'!J21 -> 716930 | K9: ='매출원가(COGS)'!K21 -> 1044008 | L9: ='매출원가(COGS)'!L21 -> 4239826 | M9: ='매출원가(COGS)'!M21 -> 1306006 | ... AS9: ='매출원가(COGS)'!AS21 -> 84632312 | AT9: Ⅱ.매출원가
A10: [a] AI 취업준비 SaaS | F10: ='매출원가(COGS)'!F18 -> 0 | G10: ='매출원가(COGS)'!G18 -> 0 | H10: ='매출원가(COGS)'!H18 -> 0 | I10: ='매출원가(COGS)'!I18 -> 0 | J10: ='매출원가(COGS)'!J18 -> 578330 | K10: ='매출원가(COGS)'!K18 -> 871748 | L10: ='매출원가(COGS)'!L18 -> 1062286 | M10: ='매출원가(COGS)'!M18 -> 1191236 | ... AS10: ='매출원가(COGS)'!AS18 -> 61526349
A11: [b] 콘텐츠 중개 | F11: ='매출원가(COGS)'!F19 -> 0 | G11: ='매출원가(COGS)'!G19 -> 0 | H11: ='매출원가(COGS)'!H19 -> 0 | I11: ='매출원가(COGS)'!I19 -> 0 | J11: ='매출원가(COGS)'!J19 -> 0 | K11: ='매출원가(COGS)'!K19 -> 0 | L11: ='매출원가(COGS)'!L19 -> 0 | M11: ='매출원가(COGS)'!M19 -> 0 | ... AS11: ='매출원가(COGS)'!AS19 -> 13273061
A12: [c] 자체 콘텐츠·컨퍼런스 | F12: ='매출원가(COGS)'!F20 -> 49500 | G12: ='매출원가(COGS)'!G20 -> 85800 | H12: ='매출원가(COGS)'!H20 -> 105600 | I12: ='매출원가(COGS)'!I20 -> 118800 | J12: ='매출원가(COGS)'!J20 -> 138600 | K12: ='매출원가(COGS)'!K20 -> 172260 | L12: ='매출원가(COGS)'!L20 -> 3177540 | M12: ='매출원가(COGS)'!M20 -> 114770 | ... AS12: ='매출원가(COGS)'!AS20 -> 9832902
A13: 매출총이익 | F13: =F5-F9 -> 1450500 | G13: =G5-G9 -> 2514200 | H13: =H5-H9 -> 3094400 | I13: =I5-I9 -> 3481200 | J13: =J5-J9 -> 4293070 | K13: =K5-K9 -> 4691992 | L13: =L5-L9 -> 4962174 | M13: =M5-M9 -> 5123870 | ... AS13: =AS5-AS9 -> 255879577 | AT13: Ⅲ.매출총손익
A14: 매출총이익률 | F14: =IF(F5=0,0,F13/F5) -> 0.967 | G14: =IF(G5=0,0,G13/G5) -> 0.967 | H14: =IF(H5=0,0,H13/H5) -> 0.967 | I14: =IF(I5=0,0,I13/I5) -> 0.967 | J14: =IF(J5=0,0,J13/J5) -> 0.8569002 | K14: =IF(K5=0,0,K13/K5) -> 0.81799024 | L14: =IF(L5=0,0,L13/L5) -> 0.53924951 | M14: =IF(M5=0,0,M13/M5) -> 0.79688473 | ... AS14: =IF(AS5=0,0,AS13/AS5) -> 0.75145563
A15: [a] 매출총이익률 | F15: =IF(F6=0,0,(F6-F10)/F6) -> 0 | G15: =IF(G6=0,0,(G6-G10)/G6) -> 0 | H15: =IF(H6=0,0,(H6-H10)/H6) -> 0 | I15: =IF(I6=0,0,(I6-I10)/I6) -> 0 | J15: =IF(J6=0,0,(J6-J10)/J6) -> 0.28601235 | K15: =IF(K6=0,0,(K6-K10)/K6) -> 0.52519172 | L15: =IF(L6=0,0,(L6-L10)/L6) -> 0.57542526 | M15: =IF(M6=0,0,(M6-M10)/M6) -> 0.59646477 | ... AS15: =IF(AS6=0,0,(AS6-AS10)/AS6) -> 0.76262479
A16: [b] 매출총이익률 | F16: =IF(F7=0,0,(F7-F11)/F7) -> 0 | G16: =IF(G7=0,0,(G7-G11)/G7) -> 0 | H16: =IF(H7=0,0,(H7-H11)/H7) -> 0 | I16: =IF(I7=0,0,(I7-I11)/I7) -> 0 | J16: =IF(J7=0,0,(J7-J11)/J7) -> 0 | K16: =IF(K7=0,0,(K7-K11)/K7) -> 0 | L16: =IF(L7=0,0,(L7-L11)/L7) -> 0 | M16: =IF(M7=0,0,(M7-M11)/M7) -> 0 | ... AS16: =IF(AS7=0,0,(AS7-AS11)/AS7) -> 0.52893084
A17: [c] 매출총이익률 | F17: =IF(F8=0,0,(F8-F12)/F8) -> 0.967 | G17: =IF(G8=0,0,(G8-G12)/G8) -> 0.967 | H17: =IF(H8=0,0,(H8-H12)/H8) -> 0.967 | I17: =IF(I8=0,0,(I8-I12)/I8) -> 0.967 | J17: =IF(J8=0,0,(J8-J12)/J8) -> 0.967 | K17: =IF(K8=0,0,(K8-K12)/K8) -> 0.95583077 | L17: =IF(L8=0,0,(L8-L12)/L8) -> 0.5257403 | M17: =IF(M8=0,0,(M8-M12)/M8) -> 0.96699997 | ... AS17: =IF(AS8=0,0,(AS8-AS12)/AS8) -> 0.81496557
A18: 판매비와관리비 | F18: ='판관비(SG&A)'!F38 -> 8543549 | G18: ='판관비(SG&A)'!G38 -> 11270360 | H18: ='판관비(SG&A)'!H38 -> 11270360 | I18: ='판관비(SG&A)'!I38 -> 9275652 | J18: ='판관비(SG&A)'!J38 -> 9616549 | K18: ='판관비(SG&A)'!K38 -> 9270078 | L18: ='판관비(SG&A)'!L38 -> 8398313 | M18: ='판관비(SG&A)'!M38 -> 8257385 | ... AS18: ='판관비(SG&A)'!AS38 -> 284713283 | AT18: Ⅳ.판매비와관리비
A19: Labor Costs(인건비) | F19: ='판관비(SG&A)'!F33 -> 0 | G19: ='판관비(SG&A)'!G33 -> 3310693 | H19: ='판관비(SG&A)'!H33 -> 3310693 | I19: ='판관비(SG&A)'!I33 -> 3310693 | J19: ='판관비(SG&A)'!J33 -> 5153645 | K19: ='판관비(SG&A)'!K33 -> 5153645 | L19: ='판관비(SG&A)'!L33 -> 5153645 | M19: ='판관비(SG&A)'!M33 -> 5153638 | ... AS19: ='판관비(SG&A)'!AS33 -> 192096864
A20: D&A(감가상각·무형자산상각) | F20: ='판관비(SG&A)'!F34 -> 0 | G20: ='판관비(SG&A)'!G34 -> 0 | H20: ='판관비(SG&A)'!H34 -> 0 | I20: ='판관비(SG&A)'!I34 -> 0 | J20: ='판관비(SG&A)'!J34 -> 0 | K20: ='판관비(SG&A)'!K34 -> 0 | L20: ='판관비(SG&A)'!L34 -> 0 | M20: ='판관비(SG&A)'!M34 -> 0 | ... AS20: ='판관비(SG&A)'!AS34 -> 1913332
A21: R&D(연구개발비) | F21: ='판관비(SG&A)'!F35 -> 6883054 | G21: ='판관비(SG&A)'!G35 -> 7183054 | H21: ='판관비(SG&A)'!H35 -> 7183054 | I21: ='판관비(SG&A)'!I35 -> 4888702 | J21: ='판관비(SG&A)'!J35 -> 2494351 | K21: ='판관비(SG&A)'!K35 -> 1347176 | L21: ='판관비(SG&A)'!L35 -> 1347176 | M21: ='판관비(SG&A)'!M35 -> 1347174 | ... AS21: ='판관비(SG&A)'!AS35 -> 21200000
A22: S&M(판매및마케팅비) | F22: ='판관비(SG&A)'!F36 -> 0 | G22: ='판관비(SG&A)'!G36 -> 300000 | H22: ='판관비(SG&A)'!H36 -> 300000 | I22: ='판관비(SG&A)'!I36 -> 600000 | J22: ='판관비(SG&A)'!J36 -> 1400000 | K22: ='판관비(SG&A)'!K36 -> 2100000 | L22: ='판관비(SG&A)'!L36 -> 1200000 | M22: ='판관비(SG&A)'!M36 -> 1100000 | ... AS22: ='판관비(SG&A)'!AS36 -> 46471087
A23: Other G&A(기타관리비) | F23: ='판관비(SG&A)'!F37 -> 1660495 | G23: ='판관비(SG&A)'!G37 -> 476613 | H23: ='판관비(SG&A)'!H37 -> 476613 | I23: ='판관비(SG&A)'!I37 -> 476257 | J23: ='판관비(SG&A)'!J37 -> 568553 | K23: ='판관비(SG&A)'!K37 -> 669257 | L23: ='판관비(SG&A)'!L37 -> 697492 | M23: ='판관비(SG&A)'!M37 -> 656573 | ... AS23: ='판관비(SG&A)'!AS37 -> 23032000
A24: 영업이익(손실) | F24: =F13-F18 -> -7093049 | G24: =G13-G18 -> -8756160 | H24: =H13-H18 -> -8175960 | I24: =I13-I18 -> -5794452 | J24: =J13-J18 -> -5323479 | K24: =K13-K18 -> -4578086 | L24: =L13-L18 -> -3436139 | M24: =M13-M18 -> -3133515 | ... AS24: =AS13-AS18 -> -28833706 | AT24: Ⅴ.영업손익
A25: 영업이익률 | F25: =IF(F5=0,0,F24/F5) -> -4.7286993 | G25: =IF(G5=0,0,G24/G5) -> -3.3677538 | H25: =IF(H5=0,0,H24/H5) -> -2.5549875 | I25: =IF(I5=0,0,I24/I5) -> -1.60957 | J25: =IF(J5=0,0,J24/J5) -> -1.0625707 | K25: =IF(K5=0,0,K24/K5) -> -0.79813215 | L25: =IF(L5=0,0,L24/L5) -> -0.37341219 | M25: =IF(M5=0,0,M24/M5) -> -0.48733677 | ... AS25: =IF(AS5=0,0,AS24/AS5) -> -0.084677531
A26: EBITDA(영업이익+감가상각비) | F26: =F24+F20 -> -7093049 | G26: =G24+G20 -> -8756160 | H26: =H24+H20 -> -8175960 | I26: =I24+I20 -> -5794452 | J26: =J24+J20 -> -5323479 | K26: =K24+K20 -> -4578086 | L26: =L24+L20 -> -3436139 | M26: =M24+M20 -> -3133515 | ... AS26: =AS24+AS20 -> -26920374
A27: 영업외수익 | F27: =F28+F29 -> 0 | G27: =G28+G29 -> 5141680 | H27: =H28+H29 -> 5141680 | I27: =I28+I29 -> 4113344 | J27: =J28+J29 -> 3085008 | K27: =K28+K29 -> 2056672 | L27: =L28+L29 -> 2071672 | M27: =M28+M29 -> 2093081 | ... AS27: =AS28+AS29 -> 67762020 | AT27: Ⅵ.영업외수익
A28: 이자수익 | B28: 2026~: 전월 말 현금 × 연 1.8% ÷ 12 | F28: 0 | G28: 0 | H28: 0 | I28: 0 | J28: 0 | K28: 0 | L28: 15000 | M28: 36410 | N28: 298186 | O28: 261372 | P28: 238020 | Q28: 227934 | R28: 937939 | S28: 944999 | T28: 927558 | U28: 903045 | V28: 890511 | W28: 886277 | X28: 873416 | Y28: 905437 | Z28: 839991 | AA28: 836193 | AB28: 838857 | AC28: 845646 | AD28: 835459 | AE28: 918468 | AF28: 908592 | AG28: 896830 | AH28: 911693 | AI28: 927743 | AJ28: 918716 | AK28: 965620 | AL28: 946110 | AM28: 927695 | AN28: 931633 | AO28: 956582 | AP28: =SUM(F28:M28) -> 51410 | AQ28: =SUM(N28:Y28) -> 8294694 | AR28: =SUM(Z28:AK28) -> 10643808 | AS28: =SUM(AL28:AO28) -> 3762020 | AT28: 1.이자수익
A29: 정부보조금·기타잡이익 | B29: 2025: 신고서 기타잡이익(창업지원금 가정) | F29: 0 | G29: 5141680 | H29: 5141680 | I29: 4113344 | J29: 3085008 | K29: 2056672 | L29: 2056672 | M29: 2056671 | N29: 0 | O29: 0 | P29: 0 | Q29: 0 | R29: 7000000 | S29: 7000000 | T29: 7000000 | U29: 7000000 | V29: 7000000 | W29: 7000000 | X29: 23000000 | Y29: 16000000 | Z29: 16000000 | AA29: 16000000 | AB29: 16000000 | AC29: 16000000 | AD29: 16000000 | AE29: 16000000 | AF29: 16000000 | AG29: 16000000 | AH29: 16000000 | AI29: 16000000 | AJ29: 16000000 | AK29: 16000000 | AL29: 16000000 | AM29: 16000000 | AN29: 16000000 | AO29: 16000000 | AP29: =SUM(F29:M29) -> 23651727 | AQ29: =SUM(N29:Y29) -> 81000000 | AR29: =SUM(Z29:AK29) -> 192000000 | AS29: =SUM(AL29:AO29) -> 64000000 | AT29: 28.기타잡이익
A30: 영업외비용 | F30: =F31+F32 -> 0 | G30: =G31+G32 -> 0 | H30: =H31+H32 -> 0 | I30: =I31+I32 -> 0 | J30: =J31+J32 -> 0 | K30: =K31+K32 -> 0 | L30: =L31+L32 -> 0 | M30: =M31+M32 -> 438822 | ... AS30: =AS31+AS32 -> 1564629 | AT30: Ⅶ.영업외비용
A31: 이자비용 | B31: 장기차입금 2억 × 연 2.5% ÷ 12 | F31: 0 | G31: 0 | H31: 0 | I31: 0 | J31: 0 | K31: 0 | L31: 0 | M31: 435982 | N31: 416667 | O31: 416667 | P31: 416667 | Q31: 416667 | R31: 416667 | S31: 416667 | T31: 416667 | U31: 416667 | V31: 416667 | W31: 416667 | X31: 416667 | Y31: 416667 | Z31: 416667 | AA31: 416667 | AB31: 416667 | AC31: 416667 | AD31: 416667 | AE31: 416667 | AF31: 416667 | AG31: 416667 | AH31: 416667 | AI31: 416667 | AJ31: 416667 | AK31: 405093 | AL31: 393519 | AM31: 381944 | AN31: 370370 | AO31: 358796 | AP31: =SUM(F31:M31) -> 435982 | AQ31: =SUM(N31:Y31) -> 5000004 | AR31: =SUM(Z31:AK31) -> 4988430 | AS31: =SUM(AL31:AO31) -> 1504629 | AT31: 1.이자비용
A32: 기타잡손실(환차손 등) | F32: 0 | G32: 0 | H32: 0 | I32: 0 | J32: 0 | K32: 0 | L32: 0 | M32: 2840 | N32: 15000 | O32: 15000 | P32: 15000 | Q32: 15000 | R32: 15000 | S32: 15000 | T32: 15000 | U32: 15000 | V32: 15000 | W32: 15000 | X32: 15000 | Y32: 15000 | Z32: 15000 | AA32: 15000 | AB32: 15000 | AC32: 15000 | AD32: 15000 | AE32: 15000 | AF32: 15000 | AG32: 15000 | AH32: 15000 | AI32: 15000 | AJ32: 15000 | AK32: 15000 | AL32: 15000 | AM32: 15000 | AN32: 15000 | AO32: 15000 | AP32: =SUM(F32:M32) -> 2840 | AQ32: =SUM(N32:Y32) -> 180000 | AR32: =SUM(Z32:AK32) -> 180000 | AS32: =SUM(AL32:AO32) -> 60000 | AT32: 21.기타잡손실
A33: 법인세비용차감전순이익(손실) | F33: =F24+F27-F30 -> -7093049 | G33: =G24+G27-G30 -> -3614480 | H33: =H24+H27-H30 -> -3034280 | I33: =I24+I27-I30 -> -1681108 | J33: =J24+J27-J30 -> -2238471 | K33: =K24+K27-K30 -> -2521414 | L33: =L24+L27-L30 -> -1364467 | M33: =M24+M27-M30 -> -1479256 | ... AS33: =AS24+AS27-AS30 -> 37363685 | AT33: Ⅷ.법인세비용차감전손익
A34: 법인세비용 | B34: 누적 결손(이월결손금)으로 0원 가정 | F34: 0 | G34: 0 | H34: 0 | I34: 0 | J34: 0 | K34: 0 | L34: 0 | M34: 0 | N34: 0 | O34: 0 | P34: 0 | Q34: 0 | R34: 0 | S34: 0 | T34: 0 | U34: 0 | V34: 0 | W34: 0 | X34: 0 | Y34: 0 | Z34: 0 | AA34: 0 | AB34: 0 | AC34: 0 | AD34: 0 | AE34: 0 | AF34: 0 | AG34: 0 | AH34: 0 | AI34: 0 | AJ34: 0 | AK34: 0 | AL34: 0 | AM34: 0 | AN34: 0 | AO34: 0 | AP34: =SUM(F34:M34) -> 0 | AQ34: =SUM(N34:Y34) -> 0 | AR34: =SUM(Z34:AK34) -> 0 | AS34: =SUM(AL34:AO34) -> 0 | AT34: Ⅸ.법인세비용
A35: 당기순이익(손실) | F35: =F33-F34 -> -7093049 | G35: =G33-G34 -> -3614480 | H35: =H33-H34 -> -3034280 | I35: =I33-I34 -> -1681108 | J35: =J33-J34 -> -2238471 | K35: =K33-K34 -> -2521414 | L35: =L33-L34 -> -1364467 | M35: =M33-M34 -> -1479256 | ... AS35: =AS33-AS34 -> 37363685 | AT35: Ⅹ.당기순손익

Sheet 현금흐름표(CF)
A1: 현금흐름표(CF) 월별 · 간접법 (단위: 원)
A2: ※ 당기순이익에서 출발해 비현금비용(감가상각)과 재무상태표 운전자본 증감을 가감(간접법). 투자·재무활동은 입력값(파란색). 기말현금이 재무상태표 현금으로 연결됩니다.
A3: 항목 | B3: 산식·비고 | F3: 2025-05-31 | G3: 2025-06-30 | H3: 2025-07-31 | I3: 2025-08-31 | J3: 2025-09-30 | K3: 2025-10-31 | L3: 2025-11-30 | M3: 2025-12-31 | N3: 2026-01-31 | O3: 2026-02-28 | P3: 2026-03-31 | Q3: 2026-04-30 | R3: 2026-05-31 | S3: 2026-06-30 | T3: 2026-07-31 | U3: 2026-08-31 | V3: 2026-09-30 | W3: 2026-10-31 | X3: 2026-11-30 | Y3: 2026-12-31 | Z3: 2027-01-31 | AA3: 2027-02-28 | AB3: 2027-03-31 | AC3: 2027-04-30 | AD3: 2027-05-31 | AE3: 2027-06-30 | AF3: 2027-07-31 | AG3: 2027-08-31 | AH3: 2027-09-30 | AI3: 2027-10-31 | AJ3: 2027-11-30 | AK3: 2027-12-31 | AL3: 2028-01-31 | AM3: 2028-02-29 | AN3: 2028-03-31 | AO3: 2028-04-30 | AP3: FY2025(5~12월) | AQ3: FY2026 | AR3: FY2027 | AS3: FY2028(1~4월) | AT3: 참고
A4: ※ 데이터구분 | F4: 실적배분 | G4: 실적배분 | H4: 실적배분 | I4: 실적배분 | J4: 실적배분 | K4: 실적배분 | L4: 실적배분 | M4: 실적배분 | N4: 가상 | O4: 가상 | P4: 가상 | Q4: 가상 | R4: 가상 | S4: 가상 | T4: 가상 | U4: 가상 | V4: 가상 | W4: 가상 | X4: 가상 | Y4: 가상 | Z4: 가상 | AA4: 가상 | AB4: 가상 | AC4: 가상 | AD4: 가상 | AE4: 가상 | AF4: 가상 | AG4: 가상 | AH4: 가상 | AI4: 가상 | AJ4: 가상 | AK4: 가상 | AL4: 가상 | AM4: 가상 | AN4: 가상 | AO4: 가상 | AP4: 연간 집계 | AQ4: 연간 집계 | AR4: 연간 집계 | AS4: 연간 집계
A5: Ⅰ. 영업활동현금흐름 | F5: =F6+F7+F8+SUM(F10:F21) -> -4593049 | G5: =G6+G7+G8+SUM(G10:G21) -> -1994480 | H5: =H6+H7+H8+SUM(H10:H21) -> -1504280 | I5: =I6+I7+I8+SUM(I10:I21) -> -151108 | J5: =J6+J7+J8+SUM(J10:J21) -> -1118471 | K5: =K6+K7+K8+SUM(K10:K21) -> -151414 | L5: =L6+L7+L8+SUM(L10:L21) -> -2634467 | M5: =M6+M7+M8+SUM(M10:M21) -> 937811 | ... AO5: =AO6+AO7+AO8+SUM(AO10:AO21) -> 31454 | AP5: =SUM(F5:M5) -> -11209458 | AQ5: =SUM(N5:Y5) -> -85196708 | AR5: =SUM(Z5:AK5) -> 90457054 | AS5: =SUM(AL5:AO5) -> 23679557
A6: 당기순이익(손실) | F6: ='손익계산서(P&L)'!F35 -> -7093049 | G6: ='손익계산서(P&L)'!G35 -> -3614480 | H6: ='손익계산서(P&L)'!H35 -> -3034280 | I6: ='손익계산서(P&L)'!I35 -> -1681108 | J6: ='손익계산서(P&L)'!J35 -> -2238471 | K6: ='손익계산서(P&L)'!K35 -> -2521414 | L6: ='손익계산서(P&L)'!L35 -> -1364467 | M6: ='손익계산서(P&L)'!M35 -> -1479256 | ... AO6: ='손익계산서(P&L)'!AO35 -> 31628416 | AP6: =SUM(F6:M6) -> -23026525 | AQ6: =SUM(N6:Y6) -> -130364048 | AR6: =SUM(Z6:AK6) -> 18492086 | AS6: =SUM(AL6:AO6) -> 37363685
A7: 감가상각비 가산 | F7: ='판관비(SG&A)'!F11 -> 0 | G7: ='판관비(SG&A)'!G11 -> 0 | H7: ='판관비(SG&A)'!H11 -> 0 | I7: ='판관비(SG&A)'!I11 -> 0 | J7: ='판관비(SG&A)'!J11 -> 0 | K7: ='판관비(SG&A)'!K11 -> 0 | L7: ='판관비(SG&A)'!L11 -> 0 | M7: ='판관비(SG&A)'!M11 -> 0 | ... AO7: ='판관비(SG&A)'!AO11 -> 420000 | AP7: =SUM(F7:M7) -> 0 | AQ7: =SUM(N7:Y7) -> 1686665 | AR7: =SUM(Z7:AK7) -> 4569999 | AS7: =SUM(AL7:AO7) -> 1680000
A8: 무형자산상각비 가산 | F8: ='판관비(SG&A)'!F12 -> 0 | G8: ='판관비(SG&A)'!G12 -> 0 | H8: ='판관비(SG&A)'!H12 -> 0 | I8: ='판관비(SG&A)'!I12 -> 0 | J8: ='판관비(SG&A)'!J12 -> 0 | K8: ='판관비(SG&A)'!K12 -> 0 | L8: ='판관비(SG&A)'!L12 -> 0 | M8: ='판관비(SG&A)'!M12 -> 0 | ... AO8: ='판관비(SG&A)'!AO12 -> 58333 | AP8: =SUM(F8:M8) -> 0 | AQ8: =SUM(N8:Y8) -> 250000 | AR8: =SUM(Z8:AK8) -> 533331 | AS8: =SUM(AL8:AO8) -> 233332
A9: [운전자본 변동]
A10: 매출채권 감소(증가) | F10: =0-'재무상태표(BS)'!F8 -> 0 | G10: ='재무상태표(BS)'!F8-'재무상태표(BS)'!G8 -> 0 | H10: ='재무상태표(BS)'!G8-'재무상태표(BS)'!H8 -> 0 | I10: ='재무상태표(BS)'!H8-'재무상태표(BS)'!I8 -> 0 | J10: ='재무상태표(BS)'!I8-'재무상태표(BS)'!J8 -> 0 | K10: ='재무상태표(BS)'!J8-'재무상태표(BS)'!K8 -> 0 | L10: ='재무상태표(BS)'!K8-'재무상태표(BS)'!L8 -> 0 | M10: ='재무상태표(BS)'!L8-'재무상태표(BS)'!M8 -> 0 | N10: ='재무상태표(BS)'!M8-'재무상태표(BS)'!N8 -> 0 | ... AO10: ='재무상태표(BS)'!AN8-'재무상태표(BS)'!AO8 -> -4950000 | AP10: =SUM(F10:M10) -> 0 | AQ10: =SUM(N10:Y10) -> -4162400 | AR10: =SUM(Z10:AK10) -> -3097600 | AS10: =SUM(AL10:AO10) -> -53020000
A11: 미수금(PG) 감소(증가) | F11: =0-'재무상태표(BS)'!F9 -> 0 | G11: ='재무상태표(BS)'!F9-'재무상태표(BS)'!G9 -> 0 | H11: ='재무상태표(BS)'!G9-'재무상태표(BS)'!H9 -> 0 | I11: ='재무상태표(BS)'!H9-'재무상태표(BS)'!I9 -> 0 | J11: ='재무상태표(BS)'!I9-'재무상태표(BS)'!J9 -> 0 | K11: ='재무상태표(BS)'!J9-'재무상태표(BS)'!K9 -> 0 | L11: ='재무상태표(BS)'!K9-'재무상태표(BS)'!L9 -> 0 | M11: ='재무상태표(BS)'!L9-'재무상태표(BS)'!M9 -> 0 | N11: ='재무상태표(BS)'!M9-'재무상태표(BS)'!N9 -> -1370567 | ... AO11: ='재무상태표(BS)'!AN9-'재무상태표(BS)'!AO9 -> 381090 | AP11: =SUM(F11:M11) -> 0 | AQ11: =SUM(N11:Y11) -> -5467814 | AR11: =SUM(Z11:AK11) -> -5338336 | AS11: =SUM(AL11:AO11) -> -8360167
A12: 선급금 감소(증가) | F12: =0-'재무상태표(BS)'!F10 -> 0 | G12: ='재무상태표(BS)'!F10-'재무상태표(BS)'!G10 -> 0 | H12: ='재무상태표(BS)'!G10-'재무상태표(BS)'!H10 -> 0 | I12: ='재무상태표(BS)'!H10-'재무상태표(BS)'!I10 -> 0 | J12: ='재무상태표(BS)'!I10-'재무상태표(BS)'!J10 -> 0 | K12: ='재무상태표(BS)'!J10-'재무상태표(BS)'!K10 -> 0 | L12: ='재무상태표(BS)'!K10-'재무상태표(BS)'!L10 -> -500000 | M12: ='재무상태표(BS)'!L10-'재무상태표(BS)'!M10 -> -451480 | N12: ='재무상태표(BS)'!M10-'재무상태표(BS)'!N10 -> 951480 | ... AO12: ='재무상태표(BS)'!AN10-'재무상태표(BS)'!AO10 -> 1350000 | AP12: =SUM(F12:M12) -> -951480 | AQ12: =SUM(N12:Y12) -> 951480 | AR12: =SUM(Z12:AK12) -> 0 | AS12: =SUM(AL12:AO12) -> 0
A13: 부가세대급금 감소(증가) | F13: =0-'재무상태표(BS)'!F11 -> 0 | G13: ='재무상태표(BS)'!F11-'재무상태표(BS)'!G11 -> 0 | H13: ='재무상태표(BS)'!G11-'재무상태표(BS)'!H11 -> 0 | I13: ='재무상태표(BS)'!H11-'재무상태표(BS)'!I11 -> 0 | J13: ='재무상태표(BS)'!I11-'재무상태표(BS)'!J11 -> 0 | K13: ='재무상태표(BS)'!J11-'재무상태표(BS)'!K11 -> 0 | L13: ='재무상태표(BS)'!K11-'재무상태표(BS)'!L11 -> 0 | M13: ='재무상태표(BS)'!L11-'재무상태표(BS)'!M11 -> 0 | N13: ='재무상태표(BS)'!M11-'재무상태표(BS)'!N11 -> -178764 | ... AO13: ='재무상태표(BS)'!AN11-'재무상태표(BS)'!AO11 -> 0 | AP13: =SUM(F13:M13) -> 0 | AQ13: =SUM(N13:Y13) -> 0 | AR13: =SUM(Z13:AK13) -> 0 | AS13: =SUM(AL13:AO13) -> 0
A14: 매입채무 증가(감소) | F14: ='재무상태표(BS)'!F19-0 -> 0 | G14: ='재무상태표(BS)'!G19-'재무상태표(BS)'!F19 -> 0 | H14: ='재무상태표(BS)'!H19-'재무상태표(BS)'!G19 -> 0 | I14: ='재무상태표(BS)'!I19-'재무상태표(BS)'!H19 -> 0 | J14: ='재무상태표(BS)'!J19-'재무상태표(BS)'!I19 -> 0 | K14: ='재무상태표(BS)'!K19-'재무상태표(BS)'!J19 -> 0 | L14: ='재무상태표(BS)'!L19-'재무상태표(BS)'!K19 -> 0 | M14: ='재무상태표(BS)'!M19-'재무상태표(BS)'!L19 -> 56354 | N14: ='재무상태표(BS)'!N19-'재무상태표(BS)'!M19 -> 1614371 | ... AO14: ='재무상태표(BS)'!AO19-'재무상태표(BS)'!AN19 -> 448995 | AP14: =SUM(F14:M14) -> 56354 | AQ14: =SUM(N14:Y14) -> 6708695 | AR14: =SUM(Z14:AK14) -> 5914743 | AS14: =SUM(AL14:AO14) -> 2547335
A15: 미지급금 증가(감소) | F15: ='재무상태표(BS)'!F20-0 -> 2500000 | G15: ='재무상태표(BS)'!G20-'재무상태표(BS)'!F20 -> 1500000 | H15: ='재무상태표(BS)'!H20-'재무상태표(BS)'!G20 -> 1500000 | I15: ='재무상태표(BS)'!I20-'재무상태표(BS)'!H20 -> 1500000 | J15: ='재무상태표(BS)'!J20-'재무상태표(BS)'!I20 -> 1000000 | K15: ='재무상태표(BS)'!K20-'재무상태표(BS)'!J20 -> 1000000 | L15: ='재무상태표(BS)'!L20-'재무상태표(BS)'!K20 -> 500000 | M15: ='재무상태표(BS)'!M20-'재무상태표(BS)'!L20 -> 488590 | N15: ='재무상태표(BS)'!N20-'재무상태표(BS)'!M20 -> -6543390 | ... AO15: ='재무상태표(BS)'!AO20-'재무상태표(BS)'!AN20 -> 1336147 | AP15: =SUM(F15:M15) -> 9988590 | AQ15: =SUM(N15:Y15) -> -3926047 | AR15: =SUM(Z15:AK15) -> 3732495 | AS15: =SUM(AL15:AO15) -> 7727516
A16: 예수금 증가(감소) | F16: ='재무상태표(BS)'!F21-0 -> 0 | G16: ='재무상태표(BS)'!G21-'재무상태표(BS)'!F21 -> 120000 | H16: ='재무상태표(BS)'!H21-'재무상태표(BS)'!G21 -> 30000 | I16: ='재무상태표(BS)'!I21-'재무상태표(BS)'!H21 -> 30000 | J16: ='재무상태표(BS)'!J21-'재무상태표(BS)'!I21 -> 120000 | K16: ='재무상태표(BS)'!K21-'재무상태표(BS)'!J21 -> 50000 | L16: ='재무상태표(BS)'!L21-'재무상태표(BS)'!K21 -> 50000 | M16: ='재무상태표(BS)'!M21-'재무상태표(BS)'!L21 -> 175420 | N16: ='재무상태표(BS)'!N21-'재무상태표(BS)'!M21 -> 1778980 | ... AO16: ='재무상태표(BS)'!AO21-'재무상태표(BS)'!AN21 -> 0 | AP16: =SUM(F16:M16) -> 575420 | AQ16: =SUM(N16:Y16) -> 4438580 | AR16: =SUM(Z16:AK16) -> 2951720 | AS16: =SUM(AL16:AO16) -> 398286
A17: 셀러 정산 예수금 증가(감소) | F17: ='재무상태표(BS)'!F22-0 -> 0 | G17: ='재무상태표(BS)'!G22-'재무상태표(BS)'!F22 -> 0 | H17: ='재무상태표(BS)'!H22-'재무상태표(BS)'!G22 -> 0 | I17: ='재무상태표(BS)'!I22-'재무상태표(BS)'!H22 -> 0 | J17: ='재무상태표(BS)'!J22-'재무상태표(BS)'!I22 -> 0 | K17: ='재무상태표(BS)'!K22-'재무상태표(BS)'!J22 -> 0 | L17: ='재무상태표(BS)'!L22-'재무상태표(BS)'!K22 -> 0 | M17: ='재무상태표(BS)'!M22-'재무상태표(BS)'!L22 -> 0 | N17: ='재무상태표(BS)'!N22-'재무상태표(BS)'!M22 -> 0 | ... AO17: ='재무상태표(BS)'!AO22-'재무상태표(BS)'!AN22 -> -3580712 | AP17: =SUM(F17:M17) -> 0 | AQ17: =SUM(N17:Y17) -> 7451793 | AR17: =SUM(Z17:AK17) -> 6534799 | AS17: =SUM(AL17:AO17) -> 12999750
A18: 부가세예수금 증가(감소) | F18: ='재무상태표(BS)'!F23-0 -> 0 | G18: ='재무상태표(BS)'!G23-'재무상태표(BS)'!F23 -> 0 | H18: ='재무상태표(BS)'!H23-'재무상태표(BS)'!G23 -> 0 | I18: ='재무상태표(BS)'!I23-'재무상태표(BS)'!H23 -> 0 | J18: ='재무상태표(BS)'!J23-'재무상태표(BS)'!I23 -> 0 | K18: ='재무상태표(BS)'!K23-'재무상태표(BS)'!J23 -> 0 | L18: ='재무상태표(BS)'!L23-'재무상태표(BS)'!K23 -> 0 | M18: ='재무상태표(BS)'!M23-'재무상태표(BS)'!L23 -> 0 | N18: ='재무상태표(BS)'!N23-'재무상태표(BS)'!M23 -> 0 | ... AO18: ='재무상태표(BS)'!AO23-'재무상태표(BS)'!AN23 -> -13813448 | AP18: =SUM(F18:M18) -> 0 | AQ18: =SUM(N18:Y18) -> 5871359 | AR18: =SUM(Z18:AK18) -> 8645149 | AS18: =SUM(AL18:AO18) -> -7162083
A19: 선수수익 증가(감소) | F19: ='재무상태표(BS)'!F24-0 -> 0 | G19: ='재무상태표(BS)'!G24-'재무상태표(BS)'!F24 -> 0 | H19: ='재무상태표(BS)'!H24-'재무상태표(BS)'!G24 -> 0 | I19: ='재무상태표(BS)'!I24-'재무상태표(BS)'!H24 -> 0 | J19: ='재무상태표(BS)'!J24-'재무상태표(BS)'!I24 -> 0 | K19: ='재무상태표(BS)'!K24-'재무상태표(BS)'!J24 -> 0 | L19: ='재무상태표(BS)'!L24-'재무상태표(BS)'!K24 -> 0 | M19: ='재무상태표(BS)'!M24-'재무상태표(BS)'!L24 -> 0 | N19: ='재무상태표(BS)'!N24-'재무상태표(BS)'!M24 -> 1509263 | ... AO19: ='재무상태표(BS)'!AO24-'재무상태표(BS)'!AN24 -> -4927367 | AP19: =SUM(F19:M19) -> 0 | AQ19: =SUM(N19:Y19) -> 33513212 | AR19: =SUM(Z19:AK19) -> 47518668 | AS19: =SUM(AL19:AO19) -> 29271903
A20: 선수금 증가(감소) | F20: ='재무상태표(BS)'!F25-0 -> 0 | G20: ='재무상태표(BS)'!G25-'재무상태표(BS)'!F25 -> 0 | H20: ='재무상태표(BS)'!H25-'재무상태표(BS)'!G25 -> 0 | I20: ='재무상태표(BS)'!I25-'재무상태표(BS)'!H25 -> 0 | J20: ='재무상태표(BS)'!J25-'재무상태표(BS)'!I25 -> 0 | K20: ='재무상태표(BS)'!K25-'재무상태표(BS)'!J25 -> 1320000 | L20: ='재무상태표(BS)'!L25-'재무상태표(BS)'!K25 -> -1320000 | M20: ='재무상태표(BS)'!M25-'재무상태표(BS)'!L25 -> 0 | N20: ='재무상태표(BS)'!N25-'재무상태표(BS)'!M25 -> 0 | ... AO20: ='재무상태표(BS)'!AO25-'재무상태표(BS)'!AN25 -> -8320000 | AP20: =SUM(F20:M20) -> 0 | AQ20: =SUM(N20:Y20) -> 0 | AR20: =SUM(Z20:AK20) -> 0 | AS20: =SUM(AL20:AO20) -> 0
